Workbook

Sheet OKUBENI
A1: Kademe-2 diff-set — okuma kılavuzu
A3: Amaç | B3: Kademe-2 diff-seti: mevcut kural (V7'nin K6 uygulaması) ile aday K6(a)/K11(d) taslağının ayrıştığı satırların tek tabloda toplanması. Yalnız okuma ve sayım; öneri uygulaması yok.
A4: Değiştirilmeyenler | B4: GEM kural seti ve FCF_TTM_2025-03_2026-06_v7_nihai.xlsx. Hiçbir FCF veya statü hücresi değiştirilmedi. FCF_SIM ve ORNEKLEM sayfalarındaki P1/P2 sütunları benzetimdir.
A5: Enflasyon muhasebesi | B5: Hiçbir satırda endeksleme, yeniden düzeltme ya da katsayı uygulaması yapılmadı. Tüm karşılaştırmalar Evo'nun hâlihazırda düzeltilmiş (aynı satın alma gücündeki) serisi üzerinden. Belge rakamları yalnız "Evo'daki değer raporun hangi satır-sütunundan geliyor" sorusu için okundu (BELGE sayfası).
A6: Veri | B6: Evo hisse_finansal_tablolari_nakit_akis_tablosu_kalemleri, 2024/03–2026/06, üç kalem: kira (finansman satırı), MDV+MODV alımı, YAGM alımı; try_donemsel (kümülatif), try_ceyreklik, try_ttm. 05.10.2026 sorguları. Kira 348, MDV 586, YAGM 141 şirkette dolu. Mekanik köprü Evo try_ttm ile 5.009 satırın 5.004'ünde aynı.
A7: Kapsam | B7: V7: 508 şirket × 6 dönem × 3 kalem = 9.144 satır. Yeni radarlar (R4–R7) Evo evreninin tamamında hesaplandı; V7 kapsamı dışındakiler RADAR sayfasında "V7 kapsamında = 0" ile duruyor.
A8: Köprü | B8: Yıllık pencere (…/12): TTM = YTD. Diğerleri: TTM = YTD_cari + FY_önceki − YTD_önceki. Kaynak noktaları bu üç değerdir.
A9: İşaret katmanları | B9: KAYNAK: üç köprü noktasının her biri ayrı sütunda (> 0). ÇEYREK: pencerenin dört çeyreği; pozitif çeyrek adedi, cari yıla düşen pozitif çeyreklerin toplamı (Q1 hariç — Q1 = YTD), önceki yıla düşenlerin toplamı. TTM: Evo try_ttm işareti (yoksa mekanik).
A10: R1–R3 | B10: Mevcut V7 listeleri: R1 = Kira anapara TTM > 0 (90 satır); R2 = V7'nin kira düştüğü satırlarda FY_önceki − YTD_önceki > 1 mn ve > %5 (50 satır); R3 = V7 K6 sütununda dışlanan MDV/YAGM satırları (52 satır).
A11: R4–R5 (yeni A) | B11: Kaynak noktalarından en az biri > 0 ve TTM < 0. Kira ve capex ayrı sütun.
A12: R6–R7 (yeni B) | B12: CAPEX köprü kırığı. Çekirdek: üç nokta dolu, FY_önceki − YTD_önceki > 1 mn ve > %5 |YTD_önceki|; TTM işaretinden ve kaynak işaretinden bağımsız. Geniş: önceki yılda YTD_önceki → FY_önceki arasında ardışık raporlarda kümülatif gerileme (> 1 mn ve > %5; sıfır değerler atlanır).
A13: Yardımcı sütunlar | B13: Beş kümenin dışında: Evo TTM > 0, kaynak pozitif (herhangi), pencerede pozitif çeyrek, kira köprü çekirdek/geniş (Evo evreni tanımıyla), cari yıl kümülatif gerilemesi. V7 kapsamında pencerede en az bir pozitif çeyreği olan satır: kira 536, MDV 606, YAGM 59 (> 1 mn: 447 / 515 / 40).
A14: Aday kural benzetimi | B14: K6(a) = kaynak pozitif. K11(d) = üç nokta dolu, kaynaklar ≤ 0, fark > 1 mn ve > %5. Pilot taslağındaki metin aynen uygulandı; eşikler ve "satır kullanılmaz" hükmü sınanıyor, önerilmiyor.
... A18: Sayfalar | B18: OZET (altı çıktı, formüllü) · RADAR (satır evreni) · FCF_SIM (politika benzetimi, FCF satırı düzeyi) · ORNEKLEM (belgeli örneklem) · KACIRILAN · SINIR · BELGE · MEKANIZMA (bölüm toplamı testi).

Sheet OZET
A1: Kademe-2 diff-set — özet (V7 ve GEM değiştirilmedi; radar tetiklemesi hata hükmü değildir)
A2: Birim: mn TL, Evo ölçeği (V7 ile aynı). Hiçbir satırda endeksleme/yeniden düzeltme yapılmadı; belge rakamları yalnız Evo değerinin hangi rapor satırından geldiğini doğrulamak için okundu. Sayım formülleri RADAR, ORNEKLEM ve FCF_SIM sayfalarını okur.
A4: 1. Benzersiz toplam radar evreni (şirket-dönem-kalem)
A5: Ölçü | B5: Satır | C5: Şirket | D5: Şirket-dönem
A6: V7 kapsamı — 5 kümeden en az biri (benzersiz) | B6: =COUNTIFS(RADAR!$D$2:$D$1192,1,RADAR!$E$2:$E$1192,1) -> 537 | C6: 204 | D6: 488
A7: Beş kümenin ham toplamı (7 radar sütunu) | B7: =SUM(B23:B29) -> 684
A8: Birleştirilen mükerrer kayıt | B8: =B7-B6 -> 147
A9: kalem: Kira anapara | B9: =COUNTIFS(RADAR!$D$2:$D$1192,1,RADAR!$E$2:$E$1192,1,RADAR!$B$2:$B$1192,"Kira anapara") -> 192
A10: kalem: MDV+MODV alımı | B10: =COUNTIFS(RADAR!$D$2:$D$1192,1,RADAR!$E$2:$E$1192,1,RADAR!$B$2:$B$1192,"MDV+MODV alımı") -> 319
A11: kalem: YAGM alımı | B11: =COUNTIFS(RADAR!$D$2:$D$1192,1,RADAR!$E$2:$E$1192,1,RADAR!$B$2:$B$1192,"YAGM alımı") -> 26
A12: V7 FCF statüsü: KESİN | B12: =COUNTIFS(RADAR!$D$2:$D$1192,1,RADAR!$E$2:$E$1192,1,RADAR!$AU$2:$AU$1192,"KESİN") -> 322
A13: V7 FCF statüsü: TÜRETİLMİŞ | B13: =COUNTIFS(RADAR!$D$2:$D$1192,1,RADAR!$E$2:$E$1192,1,RADAR!$AU$2:$AU$1192,"TÜRETİLMİŞ") -> 57
A14: V7 FCF statüsü: KOŞULLU | B14: =COUNTIFS(RADAR!$D$2:$D$1192,1,RADAR!$E$2:$E$1192,1,RADAR!$AU$2:$AU$1192,"KOŞULLU") -> 36
A15: V7 FCF statüsü: NULL | B15: =COUNTIFS(RADAR!$D$2:$D$1192,1,RADAR!$E$2:$E$1192,1,RADAR!$AU$2:$AU$1192,"NULL") -> 122
A16: V7 kapsamı dışı (Evo evreni) — yeni radarlardan en az biri | B16: =COUNTIFS(RADAR!$D$2:$D$1192,0,RADAR!$E$2:$E$1192,1) -> 94 | C16: 41
A17: Beş kümenin DIŞINDA kalan: cari yıl kümülatif gerilemesi (V7 kapsamı) | B17: =COUNTIFS(RADAR!$D$2:$D$1192,1,RADAR!$E$2:$E$1192,0,RADAR!$S$2:$S$1192,1) -> 275 | C17: 152
A18: Genişletilmiş evren = 5 küme + cari yıl gerilemesi (V7 kapsamı) | B18: =B6+B17 -> 812
A19: Cari yıl kümülatif gerilemesi: pencerenin cari yıla düşen çeyreklerinden (Q1 hariç) en az biri pozitif, toplamı > 1 mn. Kullanıcının saydığı beş kümede yok; PCILT 2025/09 ve NTHOL 2025/12 bu sınıftadır. Ayrı sütunda tutuldu, 5-küme sayısına eklenmedi.
A21: 2. Her radarın yakaladığı benzersiz satır (V7 kapsamı)
A22: Radar | B22: Satır | C22: Şirket | D22: V7 FCF statüsü KESİN / TÜRETİLMİŞ | E22: Yalnız bu radarın yakaladığı | F22: V7 kapsamı dışı (Evo evreni)
A23: R1 · 90 pozitif-TTM kira (V7) | B23: =COUNTIFS(RADAR!$G$2:$G$1192,1,RADAR!$D$2:$D$1192,1) -> 90 | C23: 46 | D23: =COUNTIFS(RADAR!$G$2:$G$1192,1,RADAR!$D$2:$D$1192,1,RADAR!$AU$2:$AU$1192,"KESİN")+COUNTIFS(RADAR!$G$2:$G$1192,1,RADAR!$D$2:$D$1192,1,RADAR!$AU$2:$AU$1192,"TÜRETİLMİŞ") -> 82 | E23: =COUNTIFS(RADAR!$G$2:$G$1192,1,RADAR!$D$2:$D$1192,1,RADAR!$F$2:$F$1192,1) -> 86 | F23: =COUNTIFS(RADAR!$G$2:$G$1192,1,RADAR!$D$2:$D$1192,0) -> 0
A24: R2 · 50 kira baz-kırığı çekirdeği (V7) | B24: =COUNTIFS(RADAR!$H$2:$H$1192,1,RADAR!$D$2:$D$1192,1) -> 50 | C24: 37 | D24: =COUNTIFS(RADAR!$H$2:$H$1192,1,RADAR!$D$2:$D$1192,1,RADAR!$AU$2:$AU$1192,"KESİN")+COUNTIFS(RADAR!$H$2:$H$1192,1,RADAR!$D$2:$D$1192,1,RADAR!$AU$2:$AU$1192,"TÜRETİLMİŞ") -> 31 | E24: =COUNTIFS(RADAR!$H$2:$H$1192,1,RADAR!$D$2:$D$1192,1,RADAR!$F$2:$F$1192,1) -> 40 | F24: =COUNTIFS(RADAR!$H$2:$H$1192,1,RADAR!$D$2:$D$1192,0) -> 0
A25: R3 · 52 pozitif CAPEX (V7 K6) | B25: =COUNTIFS(RADAR!$I$2:$I$1192,1,RADAR!$D$2:$D$1192,1) -> 52 | C25: 29 | D25: =COUNTIFS(RADAR!$I$2:$I$1192,1,RADAR!$D$2:$D$1192,1,RADAR!$AU$2:$AU$1192,"KESİN")+COUNTIFS(RADAR!$I$2:$I$1192,1,RADAR!$D$2:$D$1192,1,RADAR!$AU$2:$AU$1192,"TÜRETİLMİŞ") -> 50 | E25: =COUNTIFS(RADAR!$I$2:$I$1192,1,RADAR!$D$2:$D$1192,1,RADAR!$F$2:$F$1192,1) -> 13 | F25: =COUNTIFS(RADAR!$I$2:$I$1192,1,RADAR!$D$2:$D$1192,0) -> 0
A26: R4 · YENİ A-kira: kaynak pozitif + TTM negatif | B26: =COUNTIFS(RADAR!$J$2:$J$1192,1,RADAR!$D$2:$D$1192,1) -> 62 | C26: 38 | D26: =COUNTIFS(RADAR!$J$2:$J$1192,1,RADAR!$D$2:$D$1192,1,RADAR!$AU$2:$AU$1192,"KESİN")+COUNTIFS(RADAR!$J$2:$J$1192,1,RADAR!$D$2:$D$1192,1,RADAR!$AU$2:$AU$1192,"TÜRETİLMİŞ") -> 43 | E26: =COUNTIFS(RADAR!$J$2:$J$1192,1,RADAR!$D$2:$D$1192,1,RADAR!$F$2:$F$1192,1) -> 56 | F26: =COUNTIFS(RADAR!$J$2:$J$1192,1,RADAR!$D$2:$D$1192,0) -> 4
A27: R5 · YENİ A-capex: kaynak pozitif + TTM negatif | B27: =COUNTIFS(RADAR!$K$2:$K$1192,1,RADAR!$D$2:$D$1192,1) -> 18 | C27: 14 | D27: =COUNTIFS(RADAR!$K$2:$K$1192,1,RADAR!$D$2:$D$1192,1,RADAR!$AU$2:$AU$1192,"KESİN")+COUNTIFS(RADAR!$K$2:$K$1192,1,RADAR!$D$2:$D$1192,1,RADAR!$AU$2:$AU$1192,"TÜRETİLMİŞ") -> 10 | E27: =COUNTIFS(RADAR!$K$2:$K$1192,1,RADAR!$D$2:$D$1192,1,RADAR!$F$2:$F$1192,1) -> 14 | F27: =COUNTIFS(RADAR!$K$2:$K$1192,1,RADAR!$D$2:$D$1192,0) -> 15
A28: R6 · YENİ B-capex köprü kırığı çekirdek | B28: =COUNTIFS(RADAR!$L$2:$L$1192,1,RADAR!$D$2:$D$1192,1) -> 105 | C28: 62 | D28: =COUNTIFS(RADAR!$L$2:$L$1192,1,RADAR!$D$2:$D$1192,1,RADAR!$AU$2:$AU$1192,"KESİN")+COUNTIFS(RADAR!$L$2:$L$1192,1,RADAR!$D$2:$D$1192,1,RADAR!$AU$2:$AU$1192,"TÜRETİLMİŞ") -> 69 | E28: =COUNTIFS(RADAR!$L$2:$L$1192,1,RADAR!$D$2:$D$1192,1,RADAR!$F$2:$F$1192,1) -> 6 | F28: =COUNTIFS(RADAR!$L$2:$L$1192,1,RADAR!$D$2:$D$1192,0) -> 31
A29: R7 · YENİ B-capex köprü kırığı geniş | B29: =COUNTIFS(RADAR!$M$2:$M$1192,1,RADAR!$D$2:$D$1192,1) -> 307 | C29: 134 | D29: =COUNTIFS(RADAR!$M$2:$M$1192,1,RADAR!$D$2:$D$1192,1,RADAR!$AU$2:$AU$1192,"KESİN")+COUNTIFS(RADAR!$M$2:$M$1192,1,RADAR!$D$2:$D$1192,1,RADAR!$AU$2:$AU$1192,"TÜRETİLMİŞ") -> 200 | E29: =COUNTIFS(RADAR!$M$2:$M$1192,1,RADAR!$D$2:$D$1192,1,RADAR!$F$2:$F$1192,1) -> 207 | F29: =COUNTIFS(RADAR!$M$2:$M$1192,1,RADAR!$D$2:$D$1192,0) -> 72
A30: R1–R3 mevcut V7 listeleri (V7 değerlerinden). R4–R7 Evo ham satırlarından: A = köprü noktalarından (YTD_cari, FY_önceki, YTD_önceki; yıllık pencerede yalnız YTD) en az biri > 0 ve TTM < 0. B çekirdek = üç nokta dolu, FY_önceki − YTD_önceki > 1 mn ve > %5 |YTD_önceki|, TTM işaretinden bağımsız. B geniş = önceki yılda YTD_önceki → FY_önceki arasında ardışık raporlarda kümülatif gerileme (> 1 mn ve > %5; sıfırlar atlanır).
A32: 3. Radarlar arası kesişimler (V7 kapsamı; köşegen = radarın kendi sayısı)
B33: R1 | C33: R2 | D33: R3 | E33: R4 | F33: R5 | G33: R6 | H33: R7
A34: R1 · 90 pozitif-TTM kira (V7) | B34: =SUMPRODUCT((RADAR!$G$2:$G$1192=1)*(RADAR!$G$2:$G$1192=1)*(RADAR!$D$2:$D$1192=1)) -> 90 | C34: =SUMPRODUCT((RADAR!$G$2:$G$1192=1)*(RADAR!$H$2:$H$1192=1)*(RADAR!$D$2:$D$1192=1)) -> 4 | D34: =SUMPRODUCT((RADAR!$G$2:$G$1192=1)*(RADAR!$I$2:$I$1192=1)*(RADAR!$D$2:$D$1192=1)) -> 0 | E34: =SUMPRODUCT((RADAR!$G$2:$G$1192=1)*(RADAR!$J$2:$J$1192=1)*(RADAR!$D$2:$D$1192=1)) -> 0 | F34: =SUMPRODUCT((RADAR!$G$2:$G$1192=1)*(RADAR!$K$2:$K$1192=1)*(RADAR!$D$2:$D$1192=1)) -> 0 | G34: =SUMPRODUCT((RADAR!$G$2:$G$1192=1)*(RADAR!$L$2:$L$1192=1)*(RADAR!$D$2:$D$1192=1)) -> 0 | H34: =SUMPRODUCT((RADAR!$G$2:$G$1192=1)*(RADAR!$M$2:$M$1192=1)*(RADAR!$D$2:$D$1192=1)) -> 0
A35: R2 · 50 kira baz-kırığı çekirdeği (V7) | B35: =SUMPRODUCT((RADAR!$H$2:$H$1192=1)*(RADAR!$G$2:$G$1192=1)*(RADAR!$D$2:$D$1192=1)) -> 4 | C35: =SUMPRODUCT((RADAR!$H$2:$H$1192=1)*(RADAR!$H$2:$H$1192=1)*(RADAR!$D$2:$D$1192=1)) -> 50 | D35: =SUMPRODUCT((RADAR!$H$2:$H$1192=1)*(RADAR!$I$2:$I$1192=1)*(RADAR!$D$2:$D$1192=1)) -> 0 | E35: =SUMPRODUCT((RADAR!$H$2:$H$1192=1)*(RADAR!$J$2:$J$1192=1)*(RADAR!$D$2:$D$1192=1)) -> 6 | F35: =SUMPRODUCT((RADAR!$H$2:$H$1192=1)*(RADAR!$K$2:$K$1192=1)*(RADAR!$D$2:$D$1192=1)) -> 0 | G35: =SUMPRODUCT((RADAR!$H$2:$H$1192=1)*(RADAR!$L$2:$L$1192=1)*(RADAR!$D$2:$D$1192=1)) -> 0 | H35: =SUMPRODUCT((RADAR!$H$2:$H$1192=1)*(RADAR!$M$2:$M$1192=1)*(RADAR!$D$2:$D$1192=1)) -> 0
A36: R3 · 52 pozitif CAPEX (V7 K6) | B36: =SUMPRODUCT((RADAR!$I$2:$I$1192=1)*(RADAR!$G$2:$G$1192=1)*(RADAR!$D$2:$D$1192=1)) -> 0 | C36: =SUMPRODUCT((RADAR!$I$2:$I$1192=1)*(RADAR!$H$2:$H$1192=1)*(RADAR!$D$2:$D$1192=1)) -> 0 | D36: =SUMPRODUCT((RADAR!$I$2:$I$1192=1)*(RADAR!$I$2:$I$1192=1)*(RADAR!$D$2:$D$1192=1)) -> 52 | E36: =SUMPRODUCT((RADAR!$I$2:$I$1192=1)*(RADAR!$J$2:$J$1192=1)*(RADAR!$D$2:$D$1192=1)) -> 0 | F36: =SUMPRODUCT((RADAR!$I$2:$I$1192=1)*(RADAR!$K$2:$K$1192=1)*(RADAR!$D$2:$D$1192=1)) -> 0 | G36: =SUMPRODUCT((RADAR!$I$2:$I$1192=1)*(RADAR!$L$2:$L$1192=1)*(RADAR!$D$2:$D$1192=1)) -> 36 | H36: =SUMPRODUCT((RADAR!$I$2:$I$1192=1)*(RADAR!$M$2:$M$1192=1)*(RADAR!$D$2:$D$1192=1)) -> 34
A37: R4 · YENİ A-kira: kaynak pozitif + TTM negatif | B37: =SUMPRODUCT((RADAR!$J$2:$J$1192=1)*(RADAR!$G$2:$G$1192=1)*(RADAR!$D$2:$D$1192=1)) -> 0 | C37: =SUMPRODUCT((RADAR!$J$2:$J$1192=1)*(RADAR!$H$2:$H$1192=1)*(RADAR!$D$2:$D$1192=1)) -> 6 | D37: =SUMPRODUCT((RADAR!$J$2:$J$1192=1)*(RADAR!$I$2:$I$1192=1)*(RADAR!$D$2:$D$1192=1)) -> 0 | E37: =SUMPRODUCT((RADAR!$J$2:$J$1192=1)*(RADAR!$J$2:$J$1192=1)*(RADAR!$D$2:$D$1192=1)) -> 62 | F37: =SUMPRODUCT((RADAR!$J$2:$J$1192=1)*(RADAR!$K$2:$K$1192=1)*(RADAR!$D$2:$D$1192=1)) -> 0 | G37: =SUMPRODUCT((RADAR!$J$2:$J$1192=1)*(RADAR!$L$2:$L$1192=1)*(RADAR!$D$2:$D$1192=1)) -> 0 | H37: =SUMPRODUCT((RADAR!$J$2:$J$1192=1)*(RADAR!$M$2:$M$1192=1)*(RADAR!$D$2:$D$1192=1)) -> 0
A38: R5 · YENİ A-capex: kaynak pozitif + TTM negatif | B38: =SUMPRODUCT((RADAR!$K$2:$K$1192=1)*(RADAR!$G$2:$G$1192=1)*(RADAR!$D$2:$D$1192=1)) -> 0 | C38: =SUMPRODUCT((RADAR!$K$2:$K$1192=1)*(RADAR!$H$2:$H$1192=1)*(RADAR!$D$2:$D$1192=1)) -> 0 | D38: =SUMPRODUCT((RADAR!$K$2:$K$1192=1)*(RADAR!$I$2:$I$1192=1)*(RADAR!$D$2:$D$1192=1)) -> 0 | E38: =SUMPRODUCT((RADAR!$K$2:$K$1192=1)*(RADAR!$J$2:$J$1192=1)*(RADAR!$D$2:$D$1192=1)) -> 0 | F38: =SUMPRODUCT((RADAR!$K$2:$K$1192=1)*(RADAR!$K$2:$K$1192=1)*(RADAR!$D$2:$D$1192=1)) -> 18 | G38: =SUMPRODUCT((RADAR!$K$2:$K$1192=1)*(RADAR!$L$2:$L$1192=1)*(RADAR!$D$2:$D$1192=1)) -> 1 | H38: =SUMPRODUCT((RADAR!$K$2:$K$1192=1)*(RADAR!$M$2:$M$1192=1)*(RADAR!$D$2:$D$1192=1)) -> 4
A39: R6 · YENİ B-capex köprü kırığı çekirdek | B39: =SUMPRODUCT((RADAR!$L$2:$L$1192=1)*(RADAR!$G$2:$G$1192=1)*(RADAR!$D$2:$D$1192=1)) -> 0 | C39: =SUMPRODUCT((RADAR!$L$2:$L$1192=1)*(RADAR!$H$2:$H$1192=1)*(RADAR!$D$2:$D$1192=1)) -> 0 | D39: =SUMPRODUCT((RADAR!$L$2:$L$1192=1)*(RADAR!$I$2:$I$1192=1)*(RADAR!$D$2:$D$1192=1)) -> 36 | E39: =SUMPRODUCT((RADAR!$L$2:$L$1192=1)*(RADAR!$J$2:$J$1192=1)*(RADAR!$D$2:$D$1192=1)) -> 0 | F39: =SUMPRODUCT((RADAR!$L$2:$L$1192=1)*(RADAR!$K$2:$K$1192=1)*(RADAR!$D$2:$D$1192=1)) -> 1 | G39: =SUMPRODUCT((RADAR!$L$2:$L$1192=1)*(RADAR!$L$2:$L$1192=1)*(RADAR!$D$2:$D$1192=1)) -> 105 | H39: =SUMPRODUCT((RADAR!$L$2:$L$1192=1)*(RADAR!$M$2:$M$1192=1)*(RADAR!$D$2:$D$1192=1)) -> 94
A40: R7 · YENİ B-capex köprü kırığı geniş | B40: =SUMPRODUCT((RADAR!$M$2:$M$1192=1)*(RADAR!$G$2:$G$1192=1)*(RADAR!$D$2:$D$1192=1)) -> 0 | C40: =SUMPRODUCT((RADAR!$M$2:$M$1192=1)*(RADAR!$H$2:$H$1192=1)*(RADAR!$D$2:$D$1192=1)) -> 0 | D40: =SUMPRODUCT((RADAR!$M$2:$M$1192=1)*(RADAR!$I$2:$I$1192=1)*(RADAR!$D$2:$D$1192=1)) -> 34 | E40: =SUMPRODUCT((RADAR!$M$2:$M$1192=1)*(RADAR!$J$2:$J$1192=1)*(RADAR!$D$2:$D$1192=1)) -> 0 | F40: =SUMPRODUCT((RADAR!$M$2:$M$1192=1)*(RADAR!$K$2:$K$1192=1)*(RADAR!$D$2:$D$1192=1)) -> 4 | G40: =SUMPRODUCT((RADAR!$M$2:$M$1192=1)*(RADAR!$L$2:$L$1192=1)*(RADAR!$D$2:$D$1192=1)) -> 94 | H40: =SUMPRODUCT((RADAR!$M$2:$M$1192=1)*(RADAR!$M$2:$M$1192=1)*(RADAR!$D$2:$D$1192=1)) -> 307
A41: Tetikleyen radar adedi | B41: Satır
A42: 1 radar | B42: =COUNTIFS(RADAR!$D$2:$D$1192,1,RADAR!$E$2:$E$1192,1,RADAR!$F$2:$F$1192,1) -> 422
A43: 2 radar | B43: =COUNTIFS(RADAR!$D$2:$D$1192,1,RADAR!$E$2:$E$1192,1,RADAR!$F$2:$F$1192,2) -> 83
...

Sheet RADAR
A1: Kod | B1: Kalem | C1: Dönem | D1: V7 kapsamında (1/0) | E1: 5 kümeden en az biri (1/0) | F1: Tetikleyen radar adedi (5 küme, 7 sütun) | G1: R1 · 90 pozitif-TTM kira (V7) | H1: R2 · 50 kira baz-kırığı çekirdeği (V7) | I1: R3 · 52 pozitif CAPEX (V7 K6) | J1: R4 · YENİ A-kira: kaynak pozitif + TTM negatif | K1: R5 · YENİ A-capex: kaynak pozitif + TTM negatif | L1: R6 · YENİ B-capex köprü kırığı çekirdek | M1: R7 · YENİ B-capex köprü kırığı geniş | N1: Yrd · Evo TTM > 0 | O1: Yrd · kaynak pozitif (herhangi) | P1: Yrd · pencerede pozitif çeyrek | Q1: Yrd · kira köprü çekirdek (Evo evreni) | R1: Yrd · kira köprü geniş (Evo evreni) | S1: Yrd · cari yıl kümülatif gerilemesi (>1 mn) | T1: YTD_cari | U1: FY_önceki | V1: YTD_önceki | W1: Mekanik TTM (formül) | X1: Evo try_ttm | Y1: Ç1 (pencerenin en eski çeyreği) | Z1: Ç2 | AA1: Ç3 | AB1: Ç4 (son çeyrek) | AC1: KAYNAK katmanı: YTD_cari > 0 | AD1: KAYNAK katmanı: FY_önceki > 0 | AE1: KAYNAK katmanı: YTD_önceki > 0 | AF1: Kaynak pozitif en büyük tutar | AG1: ÇEYREK katmanı: pozitif çeyrek adedi (formül) | AH1: ÇEYREK katmanı: cari yıl pozitif çeyrek toplamı (Q1 hariç) | AI1: ÇEYREK katmanı: önceki yıl kısmı pozitif çeyrek toplamı | AJ1: TTM katmanı: işaret (formül) | AK1: Köprü: FY_önceki − YTD_önceki (formül) | AL1: Köprü: fark / |YTD_önceki| (formül) | AM1: Eşik: fark > 1 mn (formül) | AN1: Eşik: fark > %5 |YTD_önceki| (formül) | AO1: V7 TTM değer | AP1: V7 formülde kullanılan | AQ1: V7 bileşen statüsü | AR1: V7 K6 bu kalemi dışladı (1/0) | AS1: V7 CFO_TTM | AT1: V7 FCF | AU1: V7 FCF statü | AV1: Anomali göstergesi (mn TL) | AW1: Anomali / |V7 FCF| (formül) | AX1: Aday K6(a) tetikler: kaynak pozitif (1/0) | AY1: Aday K11(d) tetikler: kaynak ≤0, fark >1 mn ve >%5 (1/0) | AZ1: Kaynak-pozitif noktada bölüm toplamı testi | BA1: Belgeli örneklemde (1/0)
A2: ACSEL | B2: MDV+MODV alımı | C2: 2025/03 | D2: 1 | E2: 1 | F2: =SUM(G2:M2) -> 1 | G2: 0 | H2: 0 | I2: 0 | J2: 0 | K2: 0 | L2: 0 | M2: 1 | N2: 0 | O2: 0 | P2: 1 | Q2: 0 | R2: 0 | S2: 0 | T2: -1.094 | U2: -22.519 | V2: -4.584 | W2: =IF(RIGHT(C2,2)="12",IF(ISNUMBER(T2),T2,""),IF(COUNT(T2,U2,V2)=3,T2+U2-V2,"")) -> -19.029 | X2: -19.029 | Y2: -8.715 | Z2: 1.974 | AA2: -11.193 | AB2: -1.094 | AC2: 0 | AD2: 0 | AE2: 0 | AF2: 0 | AG2: =COUNTIF(Y2:AB2,">0") -> 1 | AH2: 0 | AI2: 1.974 | AJ2: =IF(ISNUMBER(X2),IF(X2>0,"+",IF(X2<0,"−","0")),IF(ISNUMBER(W2),IF(W2>0,"+",IF(W2<0,"−","0")),"yok")) -> − | AK2: =IF(AND(RIGHT(C2,2)<>"12",ISNUMBER(U2),ISNUMBER(V2)),U2-V2,"") -> -17.935 | AL2: =IF(AND(ISNUMBER(AK2),ISNUMBER(V2)),IF(V2<>0,AK2/ABS(V2),""),"") -> -3.9125218 | AM2: =IF(ISNUMBER(AK2),IF(AK2>1,1,0),"") -> 0 | AN2: =IF(ISNUMBER(AK2),IF(AK2>0.05*ABS(V2),1,0),"") -> 0 | AO2: -19.029 | AP2: 19.029 | AQ2: KESİN | AR2: 0 | AS2: -78.993 | AT2: -98.022 | AU2: KESİN | AV2: 1.974 | AW2: =IF(AND(ISNUMBER(AV2),ISNUMBER(AT2)),IF(AT2<>0,AV2/ABS(AT2),""),"") -> 0.020138336 | AX2: 0 | AY2: 0 | BA2: 0
A3: ACSEL | B3: MDV+MODV alımı | C3: 2025/06 | D3: 1 | E3: 1 | F3: =SUM(G3:M3) -> 1 | G3: 0 | H3: 0 | I3: 0 | J3: 0 | K3: 0 | L3: 0 | M3: 1 | N3: 0 | O3: 0 | P3: 1 | Q3: 0 | R3: 0 | S3: 0 | T3: -4.602 | U3: -22.519 | V3: -13.299 | W3: =IF(RIGHT(C3,2)="12",IF(ISNUMBER(T3),T3,""),IF(COUNT(T3,U3,V3)=3,T3+U3-V3,"")) -> -13.822 | X3: -13.821 | Y3: 1.974 | Z3: -11.193 | AA3: -1.094 | AB3: -3.507 | AC3: 0 | AD3: 0 | AE3: 0 | AF3: 0 | AG3: =COUNTIF(Y3:AB3,">0") -> 1 | AH3: 0 | AI3: 1.974 | AJ3: =IF(ISNUMBER(X3),IF(X3>0,"+",IF(X3<0,"−","0")),IF(ISNUMBER(W3),IF(W3>0,"+",IF(W3<0,"−","0")),"yok")) -> − | AK3: =IF(AND(RIGHT(C3,2)<>"12",ISNUMBER(U3),ISNUMBER(V3)),U3-V3,"") -> -9.22 | AL3: =IF(AND(ISNUMBER(AK3),ISNUMBER(V3)),IF(V3<>0,AK3/ABS(V3),""),"") -> -0.69328521 | AM3: =IF(ISNUMBER(AK3),IF(AK3>1,1,0),"") -> 0 | AN3: =IF(ISNUMBER(AK3),IF(AK3>0.05*ABS(V3),1,0),"") -> 0 | AO3: -13.821 | AP3: 13.821 | AQ3: KESİN | AR3: 0 | AS3: -97.99 | AT3: -111.811 | AU3: KESİN | AV3: 1.974 | AW3: =IF(AND(ISNUMBER(AV3),ISNUMBER(AT3)),IF(AT3<>0,AV3/ABS(AT3),""),"") -> 0.017654792 | AX3: 0 | AY3: 0 | BA3: 0
A4: AFYON | B4: MDV+MODV alımı | C4: 2025/03 | D4: 1 | E4: 1 | F4: =SUM(G4:M4) -> 1 | G4: 0 | H4: 0 | I4: 0 | J4: 0 | K4: 0 | L4: 0 | M4: 1 | N4: 0 | O4: 0 | P4: 1 | Q4: 0 | R4: 0 | S4: 0 | T4: -238.282 | U4: -472.01 | V4: -50.532 | W4: =IF(RIGHT(C4,2)="12",IF(ISNUMBER(T4),T4,""),IF(COUNT(T4,U4,V4)=3,T4+U4-V4,"")) -> -659.76 | X4: -659.76 | Y4: -344.7 | Z4: 200.19 | AA4: -276.968 | AB4: -238.282 | AC4: 0 | AD4: 0 | AE4: 0 | AF4: 0 | AG4: =COUNTIF(Y4:AB4,">0") -> 1 | AH4: 0 | AI4: 200.19 | AJ4: =IF(ISNUMBER(X4),IF(X4>0,"+",IF(X4<0,"−","0")),IF(ISNUMBER(W4),IF(W4>0,"+",IF(W4<0,"−","0")),"yok")) -> − | AK4: =IF(AND(RIGHT(C4,2)<>"12",ISNUMBER(U4),ISNUMBER(V4)),U4-V4,"") -> -421.478 | AL4: =IF(AND(ISNUMBER(AK4),ISNUMBER(V4)),IF(V4<>0,AK4/ABS(V4),""),"") -> -8.3408137 | AM4: =IF(ISNUMBER(AK4),IF(AK4>1,1,0),"") -> 0 | AN4: =IF(ISNUMBER(AK4),IF(AK4>0.05*ABS(V4),1,0),"") -> 0 | AO4: -659.761 | AP4: 659.761 | AQ4: KESİN | AR4: 0 | AS4: 1436.436 | AU4: NULL | AV4: 200.19 | AW4: =IF(AND(ISNUMBER(AV4),ISNUMBER(AT4)),IF(AT4<>0,AV4/ABS(AT4),""),"") | AX4: 0 | AY4: 0 | BA4: 0
A5: AFYON | B5: MDV+MODV alımı | C5: 2025/06 | D5: 1 | E5: 1 | F5: =SUM(G5:M5) -> 1 | G5: 0 | H5: 0 | I5: 0 | J5: 0 | K5: 0 | L5: 0 | M5: 1 | N5: 0 | O5: 0 | P5: 1 | Q5: 0 | R5: 0 | S5: 0 | T5: -358.412 | U5: -472.01 | V5: -395.232 | W5: =IF(RIGHT(C5,2)="12",IF(ISNUMBER(T5),T5,""),IF(COUNT(T5,U5,V5)=3,T5+U5-V5,"")) -> -435.19 | X5: -435.189 | Y5: 200.19 | Z5: -276.968 | AA5: -238.282 | AB5: -120.129 | AC5: 0 | AD5: 0 | AE5: 0 | AF5: 0 | AG5: =COUNTIF(Y5:AB5,">0") -> 1 | AH5: 0 | AI5: 200.19 | AJ5: =IF(ISNUMBER(X5),IF(X5>0,"+",IF(X5<0,"−","0")),IF(ISNUMBER(W5),IF(W5>0,"+",IF(W5<0,"−","0")),"yok")) -> − | AK5: =IF(AND(RIGHT(C5,2)<>"12",ISNUMBER(U5),ISNUMBER(V5)),U5-V5,"") -> -76.778 | AL5: =IF(AND(ISNUMBER(AK5),ISNUMBER(V5)),IF(V5<>0,AK5/ABS(V5),""),"") -> -0.19426059 | AM5: =IF(ISNUMBER(AK5),IF(AK5>1,1,0),"") -> 0 | AN5: =IF(ISNUMBER(AK5),IF(AK5>0.05*ABS(V5),1,0),"") -> 0 | AO5: -435.189 | AP5: 435.189 | AQ5: KESİN | AR5: 0 | AS5: 949.677 | AU5: NULL | AV5: 200.19 | AW5: =IF(AND(ISNUMBER(AV5),ISNUMBER(AT5)),IF(AT5<>0,AV5/ABS(AT5),""),"") | AX5: 0 | AY5: 0 | BA5: 0
A6: AFYON | B6: MDV+MODV alımı | C6: 2026/03 | D6: 1 | E6: 1 | F6: =SUM(G6:M6) -> 1 | G6: 0 | H6: 0 | I6: 0 | J6: 0 | K6: 0 | L6: 0 | M6: 1 | N6: 0 | O6: 0 | P6: 1 | Q6: 0 | R6: 0 | S6: 0 | T6: -31.922 | U6: -774.711 | V6: -238.282 | W6: =IF(RIGHT(C6,2)="12",IF(ISNUMBER(T6),T6,""),IF(COUNT(T6,U6,V6)=3,T6+U6-V6,"")) -> -568.351 | X6: -568.351 | Y6: -120.129 | Z6: 98.159 | AA6: -514.459 | AB6: -31.922 | AC6: 0 | AD6: 0 | AE6: 0 | AF6: 0 | AG6: =COUNTIF(Y6:AB6,">0") -> 1 | AH6: 0 | AI6: 98.159 | AJ6: =IF(ISNUMBER(X6),IF(X6>0,"+",IF(X6<0,"−","0")),IF(ISNUMBER(W6),IF(W6>0,"+",IF(W6<0,"−","0")),"yok")) -> − | AK6: =IF(AND(RIGHT(C6,2)<>"12",ISNUMBER(U6),ISNUMBER(V6)),U6-V6,"") -> -536.429 | AL6: =IF(AND(ISNUMBER(AK6),ISNUMBER(V6)),IF(V6<>0,AK6/ABS(V6),""),"") -> -2.2512359 | AM6: =IF(ISNUMBER(AK6),IF(AK6>1,1,0),"") -> 0 | AN6: =IF(ISNUMBER(AK6),IF(AK6>0.05*ABS(V6),1,0),"") -> 0 | AO6: -568.351 | AP6: 568.351 | AQ6: KESİN | AR6: 0 | AS6: 762.595 | AT6: 176.34476 | AU6: TÜRETİLMİŞ | AV6: 98.159 | AW6: =IF(AND(ISNUMBER(AV6),ISNUMBER(AT6)),IF(AT6<>0,AV6/ABS(AT6),""),"") -> 0.55663124 | AX6: 0 | AY6: 0 | BA6: 0
A7: AFYON | B7: MDV+MODV alımı | C7: 2026/06 | D7: 1 | E7: 1 | F7: =SUM(G7:M7) -> 1 | G7: 0 | H7: 0 | I7: 0 | J7: 0 | K7: 0 | L7: 0 | M7: 1 | N7: 0 | O7: 0 | P7: 1 | Q7: 0 | R7: 0 | S7: 0 | T7: -61.455 | U7: -774.711 | V7: -358.412 | W7: =IF(RIGHT(C7,2)="12",IF(ISNUMBER(T7),T7,""),IF(COUNT(T7,U7,V7)=3,T7+U7-V7,"")) -> -477.754 | X7: -477.755 | Y7: 98.159 | Z7: -514.459 | AA7: -31.922 | AB7: -29.533 | AC7: 0 | AD7: 0 | AE7: 0 | AF7: 0 | AG7: =COUNTIF(Y7:AB7,">0") -> 1 | AH7: 0 | AI7: 98.159 | AJ7: =IF(ISNUMBER(X7),IF(X7>0,"+",IF(X7<0,"−","0")),IF(ISNUMBER(W7),IF(W7>0,"+",IF(W7<0,"−","0")),"yok")) -> − | AK7: =IF(AND(RIGHT(C7,2)<>"12",ISNUMBER(U7),ISNUMBER(V7)),U7-V7,"") -> -416.299 | AL7: =IF(AND(ISNUMBER(AK7),ISNUMBER(V7)),IF(V7<>0,AK7/ABS(V7),""),"") -> -1.1615097 | AM7: =IF(ISNUMBER(AK7),IF(AK7>1,1,0),"") -> 0 | AN7: =IF(ISNUMBER(AK7),IF(AK7>0.05*ABS(V7),1,0),"") -> 0 | AO7: -477.756 | AP7: 477.756 | AQ7: KESİN | AR7: 0 | AS7: 1105.409 | AU7: NULL | AV7: 98.159 | AW7: =IF(AND(ISNUMBER(AV7),ISNUMBER(AT7)),IF(AT7<>0,AV7/ABS(AT7),""),"") | AX7: 0 | AY7: 0 | BA7: 0
A8: AGROT | B8: MDV+MODV alımı | C8: 2025/03 | D8: 1 | E8: 1 | F8: =SUM(G8:M8) -> 1 | G8: 0 | H8: 0 | I8: 0 | J8: 0 | K8: 0 | L8: 0 | M8: 1 | N8: 0 | O8: 0 | P8: 1 | Q8: 0 | R8: 0 | S8: 0 | T8: -10.577 | U8: -538.899 | V8: -247.171 | W8: =IF(RIGHT(C8,2)="12",IF(ISNUMBER(T8),T8,""),IF(COUNT(T8,U8,V8)=3,T8+U8-V8,"")) -> -302.305 | X8: -302.305 | Y8: 228.957 | Z8: -92.197 | AA8: -428.488 | AB8: -10.577 | AC8: 0 | AD8: 0 | AE8: 0 | AF8: 0 | AG8: =COUNTIF(Y8:AB8,">0") -> 1 | AH8: 0 | AI8: 228.957 | AJ8: =IF(ISNUMBER(X8),IF(X8>0,"+",IF(X8<0,"−","0")),IF(ISNUMBER(W8),IF(W8>0,"+",IF(W8<0,"−","0")),"yok")) -> − | AK8: =IF(AND(RIGHT(C8,2)<>"12",ISNUMBER(U8),ISNUMBER(V8)),U8-V8,"") -> -291.728 | AL8: =IF(AND(ISNUMBER(AK8),ISNUMBER(V8)),IF(V8<>0,AK8/ABS(V8),""),"") -> -1.1802679 | AM8: =IF(ISNUMBER(AK8),IF(AK8>1,1,0),"") -> 0 | AN8: =IF(ISNUMBER(AK8),IF(AK8>0.05*ABS(V8),1,0),"") -> 0 | AO8: -302.306 | AP8: 302.306 | AQ8: KESİN | AR8: 0 | AS8: 110.965 | AT8: -191.341 | AU8: KOŞULLU | AV8: 228.957 | AW8: =IF(AND(ISNUMBER(AV8),ISNUMBER(AT8)),IF(AT8<>0,AV8/ABS(AT8),""),"") -> 1.1965914 | AX8: 0 | AY8: 0 | BA8: 0
A9: AGROT | B9: MDV+MODV alımı | C9: 2026/03 | D9: 1 | E9: 1 | F9: =SUM(G9:M9) -> 2 | G9: 0 | H9: 0 | I9: 0 | J9: 0 | K9: 0 | L9: 1 | M9: 1 | N9: 0 | O9: 0 | P9: 1 | Q9: 0 | R9: 0 | S9: 0 | T9: -80.1 | U9: -3.251 | V9: -10.577 | W9: =IF(RIGHT(C9,2)="12",IF(ISNUMBER(T9),T9,""),IF(COUNT(T9,U9,V9)=3,T9+U9-V9,"")) -> -72.774 | X9: -72.774 | AA9: 174.473 | AB9: -80.1 | AC9: 0 | AD9: 0 | AE9: 0 | AF9: 0 | AG9: =COUNTIF(Y9:AB9,">0") -> 1 | AH9: 0 | AI9: 174.473 | AJ9: =IF(ISNUMBER(X9),IF(X9>0,"+",IF(X9<0,"−","0")),IF(ISNUMBER(W9),IF(W9>0,"+",IF(W9<0,"−","0")),"yok")) -> − | AK9: =IF(AND(RIGHT(C9,2)<>"12",ISNUMBER(U9),ISNUMBER(V9)),U9-V9,"") -> 7.326 | AL9: =IF(AND(ISNUMBER(AK9),ISNUMBER(V9)),IF(V9<>0,AK9/ABS(V9),""),"") -> 0.69263496 | AM9: =IF(ISNUMBER(AK9),IF(AK9>1,1,0),"") -> 1 | AN9: =IF(ISNUMBER(AK9),IF(AK9>0.05*ABS(V9),1,0),"") -> 1 | AQ9: NULL | AR9: 0 | AS9: -1232.45 | AU9: NULL | AV9: 7.326 | AW9: =IF(AND(ISNUMBER(AV9),ISNUMBER(AT9)),IF(AT9<>0,AV9/ABS(AT9),""),"") | AX9: 0 | AY9: 1 | BA9: 0
A10: AGROT | B10: MDV+MODV alımı | C10: 2026/06 | D10: 1 | E10: 1 | F10: =SUM(G10:M10) -> 1 | G10: 0 | H10: 0 | I10: 0 | J10: 0 | K10: 0 | L10: 0 | M10: 1 | N10: 0 | O10: 0 | P10: 1 | Q10: 0 | R10: 0 | S10: 0 | U10: -3.251 | W10: =IF(RIGHT(C10,2)="12",IF(ISNUMBER(T10),T10,""),IF(COUNT(T10,U10,V10)=3,T10+U10-V10,"")) | Z10: 174.473 | AA10: -80.1 | AC10: 0 | AD10: 0 | AE10: 0 | AF10: 0 | AG10: =COUNTIF(Y10:AB10,">0") -> 1 | AH10: 0 | AI10: 174.473 | AJ10: =IF(ISNUMBER(X10),IF(X10>0,"+",IF(X10<0,"−","0")),IF(ISNUMBER(W10),IF(W10>0,"+",IF(W10<0,"−","0")),"yok")) -> yok | AK10: =IF(AND(RIGHT(C10,2)<>"12",ISNUMBER(U10),ISNUMBER(V10)),U10-V10,"") | AL10: =IF(AND(ISNUMBER(AK10),ISNUMBER(V10)),IF(V10<>0,AK10/ABS(V10),""),"") | AM10: =IF(ISNUMBER(AK10),IF(AK10>1,1,0),"") | AN10: =IF(ISNUMBER(AK10),IF(AK10>0.05*ABS(V10),1,0),"") | AQ10: NULL | AR10: 0 | AS10: -1015.625 | AU10: NULL | AV10: 174.473 | AW10: =IF(AND(ISNUMBER(AV10),ISNUMBER(AT10)),IF(AT10<>0,AV10/ABS(AT10),""),"") | AX10: 0 | AY10: 0 | BA10: 0
A11: AHGAZ | B11: Kira anapara | C11: 2025/03 | D11: 1 | E11: 1 | F11: =SUM(G11:M11) -> 1 | G11: 0 | H11: 0 | I11: 0 | J11: 1 | K11: 0 | L11: 0 | M11: 0 | N11: 0 | O11: 1 | P11: 1 | Q11: 0 | R11: 1 | S11: 0 | T11: 4.939 | U11: -103.809 | V11: -42.319 | W11: =IF(RIGHT(C11,2)="12",IF(ISNUMBER(T11),T11,""),IF(COUNT(T11,U11,V11)=3,T11+U11-V11,"")) -> -56.551 | X11: -56.55 | Y11: -152.721 | Z11: 39.892 | AA11: 51.339 | AB11: 4.939 | AC11: 1 | AD11: 0 | AE11: 0 | AF11: 4.939 | AG11: =COUNTIF(Y11:AB11,">0") -> 3 | AH11: 0 | AI11: 91.231 | AJ11: =IF(ISNUMBER(X11),IF(X11>0,"+",IF(X11<0,"−","0")),IF(ISNUMBER(W11),IF(W11>0,"+",IF(W11<0,"−","0")),"yok")) -> − | AK11: =IF(AND(RIGHT(C11,2)<>"12",ISNUMBER(U11),ISNUMBER(V11)),U11-V11,"") -> -61.49 | AL11: =IF(AND(ISNUMBER(AK11),ISNUMBER(V11)),IF(V11<>0,AK11/ABS(V11),""),"") -> -1.4530116 | AM11: =IF(ISNUMBER(AK11),IF(AK11>1,1,0),"") -> 0 | AN11: =IF(ISNUMBER(AK11),IF(AK11>0.05*ABS(V11),1,0),"") -> 0 | AO11: -56.55 | AP11: 56.55 | AQ11: KESİN | AR11: 0 | AS11: 19096.509 | AT11: 3357.519 | AU11: KESİN | AV11: 4.939 | AW11: =IF(AND(ISNUMBER(AV11),ISNUMBER(AT11)),IF(AT11<>0,AV11/ABS(AT11),""),"") -> 0.0014710267 | AX11: 1 | AY11: 0 | AZ11: YTD 2025/03 (+4.9): finansman alt toplamı tutmuyor | BA11: 0
A12: AHGAZ | B12: Kira anapara | C12: 2025/06 | D12: 1 | E12: 1 | F12: =SUM(G12:M12) -> 1 | G12: 1 | H12: 0 | I12: 0 | J12: 0 | K12: 0 | L12: 0 | M12: 0 | N12: 1 | O12: 0 | P12: 1 | Q12: 1 | R12: 1 | S12: 0 | T12: -79.054 | U12: -103.809 | V12: -195.041 | W12: =IF(RIGHT(C12,2)="12",IF(ISNUMBER(T12),T12,""),IF(COUNT(T12,U12,V12)=3,T12+U12-V12,"")) -> 12.178 | X12: 12.177 | Y12: 39.892 | Z12: 51.339 | AA12: 4.939 | AB12: -83.993 | AC12: 0 | AD12: 0 | AE12: 0 | AF12: 0 | AG12: =COUNTIF(Y12:AB12,">0") -> 3 | AH12: 0 | AI12: 91.231 | AJ12: =IF(ISNUMBER(X12),IF(X12>0,"+",IF(X12<0,"−","0")),IF(ISNUMBER(W12),IF(W12>0,"+",IF(W12<0,"−","0")),"yok")) -> + | AK12: =IF(AND(RIGHT(C12,2)<>"12",ISNUMBER(U12),ISNUMBER(V12)),U12-V12,"") -> 91.232 | AL12: =IF(AND(ISNUMBER(AK12),ISNUMBER(V12)),IF(V12<>0,AK12/ABS(V12),""),"") -> 0.46775806 | AM12: =IF(ISNUMBER(AK12),IF(AK12>1,1,0),"") -> 1 | AN12: =IF(ISNUMBER(AK12),IF(AK12>0.05*ABS(V12),1,0),"") -> 1 | AO12: 12.178 | AP12: 0 | AQ12: KESİN | AR12: 1 | AS12: 20721.501 | AT12: 12083.102 | AU12: KESİN | AV12: 91.232 | AW12: =IF(AND(ISNUMBER(AV12),ISNUMBER(AT12)),IF(AT12<>0,AV12/ABS(AT12),""),"") -> 0.007550379 | AX12: 0 | AY12: 1 | BA12: 0
A13: AHGAZ | B13: Kira anapara | C13: 2025/09 | D13: 1 | E13: 1 | F13: =SUM(G13:M13) -> 1 | G13: 0 | H13: 1 | I13: 0 | J13: 0 | K13: 0 | L13: 0 | M13: 0 | N13: 0 | O13: 0 | P13: 1 | Q13: 1 | R13: 1 | S13: 0 | T13: -113.716 | U13: -103.809 | V13: -155.148 | W13: =IF(RIGHT(C13,2)="12",IF(ISNUMBER(T13),T13,""),IF(COUNT(T13,U13,V13)=3,T13+U13-V13,"")) -> -62.377 | X13: -62.376 | Y13: 51.339 | Z13: 4.939 | AA13: -83.993 | AB13: -34.662 | AC13: 0 | AD13: 0 | AE13: 0 | AF13: 0 | AG13: =COUNTIF(Y13:AB13,">0") -> 2 | AH13: 0 | AI13: 51.339 | AJ13: =IF(ISNUMBER(X13),IF(X13>0,"+",IF(X13<0,"−","0")),IF(ISNUMBER(W13),IF(W13>0,"+",IF(W13<0,"−","0")),"yok")) -> − | AK13: =IF(AND(RIGHT(C13,2)<>"12",ISNUMBER(U13),ISNUMBER(V13)),U13-V13,"") -> 51.339 | AL13: =IF(AND(ISNUMBER(AK13),ISNUMBER(V13)),IF(V13<>0,AK13/ABS(V13),""),"") -> 0.3309034 | AM13: =IF(ISNUMBER(AK13),IF(AK13>1,1,0),"") -> 1 | AN13: =IF(ISNUMBER(AK13),IF(AK13>0.05*ABS(V13),1,0),"") -> 1 | AO13: -62.376 | AP13: 62.376 | AQ13: KESİN | AR13: 0 | AS13: 22657.665 | AT13: 13649.192 | AU13: KESİN | AV13: 51.339 | AW13: =IF(AND(ISNUMBER(AV13),ISNUMBER(AT13)),IF(AT13<>0,AV13/ABS(AT13),""),"") -> 0.0037613215 | AX13: 0 | AY13: 1 | BA13: 0
A14: AHGAZ | B14: Kira anapara | C14: 2026/03 | D14: 1 | E14: 1 | F14: =SUM(G14:M14) -> 1 | G14: 0 | H14: 0 | I14: 0 | J14: 1 | K14: 0 | L14: 0 | M14: 0 | N14: 0 | O14: 1 | P14: 0 | Q14: 0 | R14: 0 | S14: 0 | T14: -22.242 | U14: -149.905 | V14: 4.939 | W14: =IF(RIGHT(C14,2)="12",IF(ISNUMBER(T14),T14,""),IF(COUNT(T14,U14,V14)=3,T14+U14-V14,"")) -> -177.086 | X14: -177.087 | Y14: -83.993 | Z14: -34.662 | AA14: -36.189 | AB14: -22.242 | AC14: 0 | AD14: 0 | AE14: 1 | AF14: 4.939 | AG14: =COUNTIF(Y14:AB14,">0") -> 0 | AH14: 0 | AI14: 0 | AJ14: =IF(ISNUMBER(X14),IF(X14>0,"+",IF(X14<0,"−","0")),IF(ISNUMBER(W14),IF(W14>0,"+",IF(W14<0,"−","0")),"yok")) -> − | AK14: =IF(AND(RIGHT(C14,2)<>"12",ISNUMBER(U14),ISNUMBER(V14)),U14-V14,"") -> -154.844 | AL14: =IF(AND(ISNUMBER(AK14),ISNUMBER(V14)),IF(V14<>0,AK14/ABS(V14),""),"") -> -31.351286 | AM14: =IF(ISNUMBER(AK14),IF(AK14>1,1,0),"") -> 0 | AN14: =IF(ISNUMBER(AK14),IF(AK14>0.05*ABS(V14),1,0),"") -> 0 | AO14: -177.088 | AP14: 177.088 | AQ14: KESİN | AR14: 0 | AS14: 29205.005 | AT14: 22606.221 | AU14: KESİN | AV14: 4.939 | AW14: =IF(AND(ISNUMBER(AV14),ISNUMBER(AT14)),IF(AT14<>0,AV14/ABS(AT14),""),"") -> 0.00021847968 | AX14: 1 | AY14: 0 | AZ14: YTD-1 2025/03 (+4.9): finansman alt toplamı tutmuyor | BA14: 0
A15: AKHAN | B15: MDV+MODV alımı | C15: 2026/03 | D15: 1 | E15: 1 | F15: =SUM(G15:M15) -> 2 | G15: 0 | H15: 0 | I15: 0 | J15: 0 | K15: 0 | L15: 1 | M15: 1 | N15: 1 | O15: 1 | P15: 1 | Q15: 0 | R15: 0 | S15: 0 | T15: 2284.505 | U15: 2152.23 | V15: -383.33 | W15: =IF(RIGHT(C15,2)="12",IF(ISNUMBER(T15),T15,""),IF(COUNT(T15,U15,V15)=3,T15+U15-V15,"")) -> 4820.065 | X15: 4820.066 | Y15: -115.51 | AB15: 2284.505 | AC15: 1 | AD15: 1 | AE15: 0 | AF15: 2284.505 | AG15: =COUNTIF(Y15:AB15,">0") -> 1 | AH15: 0 | AI15: 0 | AJ15: =IF(ISNUMBER(X15),IF(X15>0,"+",IF(X15<0,"−","0")),IF(ISNUMBER(W15),IF(W15>0,"+",IF(W15<0,"−","0")),"yok")) -> + | AK15: =IF(AND(RIGHT(C15,2)<>"12",ISNUMBER(U15),ISNUMBER(V15)),U15-V15,"") -> 2535.56 | AL15: =IF(AND(ISNUMBER(AK15),ISNUMBER(V15)),IF(V15<>0,AK15/ABS(V15),""),"") -> 6.6145619 | AM15: =IF(ISNUMBER(AK15),IF(AK15>1,1,0),"") -> 1 | AN15: =IF(ISNUMBER(AK15),IF(AK15>0.05*ABS(V15),1,0),"") -> 1 | AQ15: NULL | AR15: 0 | AS15: -2622.368 | AU15: NULL | AV15: 2284.505 | AW15: =IF(AND(ISNUMBER(AV15),ISNUMBER(AT15)),IF(AT15<>0,AV15/ABS(AT15),""),"") | AX15: 1 | AY15: 0 | AZ15: YTD 2026/03 (+2,284.5): pozitif değer bölüm toplamına pozitif giriyor | FY-1 2025/12 (+2,152.2): pozitif değer bölüm toplamına pozitif giriyor | BA15: 0
A16: AKHAN | B16: MDV+MODV alımı | C16: 2026/06 | D16: 1 | E16: 1 | F16: =SUM(G16:M16) -> 2 | G16: 0 | H16: 0 | I16: 0 | J16: 0 | K16: 0 | L16: 1 | M16: 1 | N16: 1 | O16: 1 | P16: 1 | Q16: 0 | R16: 0 | S16: 0 | T16: -743.756 | U16: 2152.23 | V16: -498.84 | W16: =IF(RIGHT(C16,2)="12",IF(ISNUMBER(T16),T16,""),IF(COUNT(T16,U16,V16)=3,T16+U16-V16,"")) -> 1907.314 | X16: 1907.314 | AA16: 2284.505 | AB16: -3028.262 | AC16: 0 | AD16: 1 | AE16: 0 | AF16: 2152.23 | AG16: =COUNTIF(Y16:AB16,">0") -> 1 | AH16: 0 | AI16: 0 | AJ16: =IF(ISNUMBER(X16),IF(X16>0,"+",IF(X16<0,"−","0")),IF(ISNUMBER(W16),IF(W16>0,"+",IF(W16<0,"−","0")),"yok")) -> + | AK16: =IF(AND(RIGHT(C16,2)<>"12",ISNUMBER(U16),ISNUMBER(V16)),U16-V16,"") -> 2651.07 | AL16: =IF(AND(ISNUMBER(AK16),ISNUMBER(V16)),IF(V16<>0,AK16/ABS(V16),""),"") -> 5.3144696 | AM16: =IF(ISNUMBER(AK16),IF(AK16>1,1,0),"") -> 1 | AN16: =IF(ISNUMBER(AK16),IF(AK16>0.05*ABS(V16),1,0),"") -> 1 | AQ16: NULL | AR16: 0 | AS16: -667.663 | AU16: NULL | AV16: 2152.23 | AW16: =IF(AND(ISNUMBER(AV16),ISNUMBER(AT16)),IF(AT16<>0,AV16/ABS(AT16),""),"") | AX16: 1 | AY16: 0 | AZ16: FY-1 2025/12 (+2,152.2): pozitif değer bölüm toplamına pozitif giriyor | BA16: 0
A17: AKSA | B17: Kira anapara | C17: 2026/06 | D17: 1 | E17: 1 | F17: =SUM(G17:M17) -> 1 | G17: 0 | H17: 1 | I17: 0 | J17: 0 | K17: 0 | L17: 0 | M17: 0 | N17: 0 | O17: 0 | P17: 1 | Q17: 1 | R17: 1 | S17: 0 | T17: -24.242 | U17: -16.978 | V17: -18.778 | W17: =IF(RIGHT(C17,2)="12",IF(ISNUMBER(T17),T17,""),IF(COUNT(T17,U17,V17)=3,T17+U17-V17,"")) -> -22.442 | X17: -22.442 | Y17: -1.707 | Z17: 3.506 | AA17: -19.727 | AB17: -4.514 | AC17: 0 | AD17: 0 | AE17: 0 | AF17: 0 | AG17: =COUNTIF(Y17:AB17,">0") -> 1 | AH17: 0 | AI17: 3.506 | AJ17: =IF(ISNUMBER(X17),IF(X17>0,"+",IF(X17<0,"−","0")),IF(ISNUMBER(W17),IF(W17>0,"+",IF(W17<0,"−","0")),"yok")) -> − | AK17: =IF(AND(RIGHT(C17,2)<>"12",ISNUMBER(U17),ISNUMBER(V17)),U17-V17,"") -> 1.8 | AL17: =IF(AND(ISNUMBER(AK17),ISNUMBER(V17)),IF(V17<>0,AK17/ABS(V17),""),"") -> 0.095856854 | AM17: =IF(ISNUMBER(AK17),IF(AK17>1,1,0),"") -> 1 | AN17: =IF(ISNUMBER(AK17),IF(AK17>0.05*ABS(V17),1,0),"") -> 1 | AO17: -22.443 | AP17: 22.443 | AQ17: KESİN | AR17: 0 | AS17: 5532.112 | AT17: 2764.66 | AU17: KESİN | AV17: 1.8 | AW17: =IF(AND(ISNUMBER(AV17),ISNUMBER(AT17)),IF(AT17<>0,AV17/ABS(AT17),""),"") -> 0.00065107463 | AX17: 0 | AY17: 1 | BA17: 0
A18: AKSEN | B18: Kira anapara | C18: 2025/09 | D18: 1 | E18: 1 | F18: =SUM(G18:M18) -> 1 | G18: 0 | H18: 1 | I18: 0 | J18: 0 | K18: 0 | L18: 0 | M18: 0 | N18: 0 | O18: 0 | P18: 1 | Q18: 1 | R18: 1 | S18: 0 | T18: -189.498 | U18: -387.966 | V18: -433.863 | W18: =IF(RIGHT(C18,2)="12",IF(ISNUMBER(T18),T18,""),IF(COUNT(T18,U18,V18)=3,T18+U18-V18,"")) -> -143.601 | X18: -143.601 | Y18: 45.897 | Z18: -66.279 | AA18: -112.398 | AB18: -10.819 | AC18: 0 | AD18: 0 | AE18: 0 | AF18: 0 | AG18: =COUNTIF(Y18:AB18,">0") -> 1 | AH18: 0 | AI18: 45.897 | AJ18: =IF(ISNUMBER(X18),IF(X18>0,"+",IF(X18<0,"−","0")),IF(ISNUMBER(W18),IF(W18>0,"+",IF(W18<0,"−","0")),"yok")) -> − | AK18: =IF(AND(RIGHT(C18,2)<>"12",ISNUMBER(U18),ISNUMBER(V18)),U18-V18,"") -> 45.897 | AL18: =IF(AND(ISNUMBER(AK18),ISNUMBER(V18)),IF(V18<>0,AK18/ABS(V18),""),"") -> 0.10578685 | AM18: =IF(ISNUMBER(AK18),IF(AK18>1,1,0),"") -> 1 | AN18: =IF(ISNUMBER(AK18),IF(AK18>0.05*ABS(V18),1,0),"") -> 1 | AO18: -143.6 | AP18: 143.6 | AQ18: KESİN | AR18: 0 | AS18: 5974.373 | AT18: -17176.05 | AU18: KESİN | AV18: 45.897 | AW18: =IF(AND(ISNUMBER(AV18),ISNUMBER(AT18)),IF(AT18<>0,AV18/ABS(AT18),""),"") -> 0.002672151 | AX18: 0 | AY18: 1 | BA18: 0
A19: AKSUE | B19: MDV+MODV alımı | C19: 2025/03 | D19: 1 | E19: 1 | F19: =SUM(G19:M19) -> 1 | G19: 0 | H19: 0 | I19: 0 | J19: 0 | K19: 0 | L19: 0 | M19: 1 | N19: 0 | O19: 0 | P19: 1 | Q19: 0 | R19: 0 | S19: 0 | U19: -17.504 | V19: -8.339 | W19: =IF(RIGHT(C19,2)="12",IF(ISNUMBER(T19),T19,""),IF(COUNT(T19,U19,V19)=3,T19+U19-V19,"")) | Y19: 6.122 | Z19: -15.274 | AA19: -0.013 | AC19: 0 | AD19: 0 | AE19: 0 | AF19: 0 | AG19: =COUNTIF(Y19:AB19,">0") -> 1 | AH19: 0 | AI19: 6.122 | AJ19: =IF(ISNUMBER(X19),IF(X19>0,"+",IF(X19<0,"−","0")),IF(ISNUMBER(W19),IF(W19>0,"+",IF(W19<0,"−","0")),"yok")) -> yok | AK19: =IF(AND(RIGHT(C19,2)<>"12",ISNUMBER(U19),ISNUMBER(V19)),U19-V19,"") -> -9.165 | AL19: =IF(AND(ISNUMBER(AK19),ISNUMBER(V19)),IF(V19<>0,AK19/ABS(V19),""),"") -> -1.0990526 | AM19: =IF(ISNUMBER(AK19),IF(AK19>1,1,0),"") -> 0 | AN19: =IF(ISNUMBER(AK19),IF(AK19>0.05*ABS(V19),1,0),"") -> 0 | AO19: -9.164 | AP19: 9.164 | AQ19: TÜRETİLMİŞ | AR19: 0 | AS19: 10.467 | AT19: -67.743 | AU19: TÜRETİLMİŞ | AV19: 6.122 | AW19: =IF(AND(ISNUMBER(AV19),ISNUMBER(AT19)),IF(AT19<>0,AV19/ABS(AT19),""),"") -> 0.090370961 | AX19: 0 | AY19: 0 | BA19: 0
A20: ALCAR | B20: Kira anapara | C20: 2025/06 | D20: 1 | E20: 1 | F20: =SUM(G20:M20) -> 1 | G20: 0 | H20: 1 | I20: 0 | J20: 0 | K20: 0 | L20: 0 | M20: 0 | N20: 0 | O20: 0 | P20: 1 | Q20: 1 | R20: 1 | S20: 0 | T20: -34.746 | U20: -61.437 | V20: -65.364 | W20: =IF(RIGHT(C20,2)="12",IF(ISNUMBER(T20),T20,""),IF(COUNT(T20,U20,V20)=3,T20+U20-V20,"")) -> -30.819 | X20: -30.819 | Y20: 56.019 | Z20: -52.093 | AA20: -18.252 | AB20: -16.494 | AC20: 0 | AD20: 0 | AE20: 0 | AF20: 0 | AG20: =COUNTIF(Y20:AB20,">0") -> 1 | AH20: 0 | AI20: 56.019 | AJ20: =IF(ISNUMBER(X20),IF(X20>0,"+",IF(X20<0,"−","0")),IF(ISNUMBER(W20),IF(W20>0,"+",IF(W20<0,"−","0")),"yok")) -> − | AK20: =IF(AND(RIGHT(C20,2)<>"12",ISNUMBER(U20),ISNUMBER(V20)),U20-V20,"") -> 3.927 | AL20: =IF(AND(ISNUMBER(AK20),ISNUMBER(V20)),IF(V20<>0,AK20/ABS(V20),""),"") -> 0.060078943 | AM20: =IF(ISNUMBER(AK20),IF(AK20>1,1,0),"") -> 1 | AN20: =IF(ISNUMBER(AK20),IF(AK20>0.05*ABS(V20),1,0),"") -> 1 | AO20: -30.821 | AP20: 30.821 | AQ20: KESİN | AR20: 0 | AS20: 378.798 | AT20: 347.977 | AU20: KOŞULLU | AV20: 3.927 | AW20: =IF(AND(ISNUMBER(AV20),ISNUMBER(AT20)),IF(AT20<>0,AV20/ABS(AT20),""),"") -> 0.011285229 | AX20: 0 | AY20: 1 | BA20: 0
A21: ALCAR | B21: MDV+MODV alımı | C21: 2025/06 | D21: 1 | E21: 1 | F21: =SUM(G21:M21) -> 1 | G21: 0 | H21: 0 | I21: 1 | J21: 0 | K21: 0 | L21: 0 | M21: 0 | N21: 1 | O21: 1 | P21: 1 | Q21: 0 | R21: 0 | S21: 1 | T21: 1357.15 | U21: -228.62 | V21: -130.275 | W21: =IF(RIGHT(C21,2)="12",IF(ISNUMBER(T21),T21,""),IF(COUNT(T21,U21,V21)=3,T21+U21-V21,"")) -> 1258.805 | X21: 1258.804 | Y21: -90.728 | Z21: -7.617 | AA21: -15.316 | AB21: 1372.467 | AC21: 1 | AD21: 0 | AE21: 0 | AF21: 1357.15 | AG21: =COUNTIF(Y21:AB21,">0") -> 1 | AH21: 1372.467 | AI21: 0 | AJ21: =IF(ISNUMBER(X21),IF(X21>0,"+",IF(X21<0,"−","0")),IF(ISNUMBER(W21),IF(W21>0,"+",IF(W21<0,"−","0")),"yok")) -> + | AK21: =IF(AND(RIGHT(C21,2)<>"12",ISNUMBER(U21),ISNUMBER(V21)),U21-V21,"") -> -98.345 | AL21: =IF(AND(ISNUMBER(AK21),ISNUMBER(V21)),IF(V21<>0,AK21/ABS(V21),""),"") -> -0.75490309 | AM21: =IF(ISNUMBER(AK21),IF(AK21>1,1,0),"") -> 0 | AN21: =IF(ISNUMBER(AK21),IF(AK21>0.05*ABS(V21),1,0),"") -> 0 | AO21: 1258.805 | AP21: 0 | AQ21: KESİN | AR21: 1 | AS21: 378.798 | AT21: 347.977 | AU21: KOŞULLU | AV21: 1357.15 | AW21: =IF(AND(ISNUMBER(AV21),ISNUMBER(AT21)),IF(AT21<>0,AV21/ABS(AT21),""),"") -> 3.9001141 | AX21: 1 | AY21: 0 | AZ21: YTD 2025/06 (+1,357.2): kalem = yatırım bölüm toplamı | BA21: 1
A22: ALCAR | B22: MDV+MODV alımı | C22: 2026/03 | D22: 1 | E22: 1 | F22: =SUM(G22:M22) -> 1 | G22: 0 | H22: 0 | I22: 0 | J22: 0 | K22: 0 | L22: 0 | M22: 1 | N22: 0 | O22: 0 | P22: 1 | Q22: 0 | R22: 0 | S22: 0 | T22: -16.63 | U22: -55.705 | V22: -15.316 | W22: =IF(RIGHT(C22,2)="12",IF(ISNUMBER(T22),T22,""),IF(COUNT(T22,U22,V22)=3,T22+U22-V22,"")) -> -57.019 | X22: -57.019 | Y22: 1372.467 | Z22: -1390.529 | AA22: -22.327 | AB22: -16.63 | AC22: 0 | AD22: 0 | AE22: 0 | AF22: 0 | AG22: =COUNTIF(Y22:AB22,">0") -> 1 | AH22: 0 | AI22: 1372.467 | AJ22: =IF(ISNUMBER(X22),IF(X22>0,"+",IF(X22<0,"−","0")),IF(ISNUMBER(W22),IF(W22>0,"+",IF(W22<0,"−","0")),"yok")) -> − | AK22: =IF(AND(RIGHT(C22,2)<>"12",ISNUMBER(U22),ISNUMBER(V22)),U22-V22,"") -> -40.389 | AL22: =IF(AND(ISNUMBER(AK22),ISNUMBER(V22)),IF(V22<>0,AK22/ABS(V22),""),"") -> -2.6370462 | AM22: =IF(ISNUMBER(AK22),IF(AK22>1,1,0),"") -> 0 | AN22: =IF(ISNUMBER(AK22),IF(AK22>0.05*ABS(V22),1,0),"") -> 0 | AO22: -57.019 | AP22: 57.019 | AQ22: KESİN | AR22: 0 | AS22: -1098.554 | AT22: -1249.879 | AU22: KESİN | AV22: 1372.467 | AW22: =IF(AND(ISNUMBER(AV22),ISNUMBER(AT22)),IF(AT22<>0,AV22/ABS(AT22),""),"") -> 1.0980799 | AX22: 0 | AY22: 0 | BA22: 0
A23: ALCAR | B23: MDV+MODV alımı | C23: 2026/06 | D23: 1 | E23: 1 | F23: =SUM(G23:M23) -> 1 | G23: 0 | H23: 0 | I23: 0 | J23: 0 | K23: 1 | L23: 0 | M23: 0 | N23: 0 | O23: 1 | P23: 0 | Q23: 0 | R23: 0 | S23: 0 | T23: -26.185 | U23: -55.705 | V23: 1357.15 | W23: =IF(RIGHT(C23,2)="12",IF(ISNUMBER(T23),T23,""),IF(COUNT(T23,U23,V23)=3,T23+U23-V23,"")) -> -1439.04 | X23: -1439.041 | Y23: -1390.529 | Z23: -22.327 | AA23: -16.63 | AB23: -9.555 | AC23: 0 | AD23: 0 | AE23: 1 | AF23: 1357.15 | AG23: =COUNTIF(Y23:AB23,">0") -> 0 | AH23: 0 | AI23: 0 | AJ23: =IF(ISNUMBER(X23),IF(X23>0,"+",IF(X23<0,"−","0")),IF(ISNUMBER(W23),IF(W23>0,"+",IF(W23<0,"−","0")),"yok")) -> − | AK23: =IF(AND(RIGHT(C23,2)<>"12",ISNUMBER(U23),ISNUMBER(V23)),U23-V23,"") -> -1412.855 | AL23: =IF(AND(ISNUMBER(AK23),ISNUMBER(V23)),IF(V23<>0,AK23/ABS(V23),""),"") -> -1.0410456 | AM23: =IF(ISNUMBER(AK23),IF(AK23>1,1,0),"") -> 0 | AN23: =IF(ISNUMBER(AK23),IF(AK23>0.05*ABS(V23),1,0),"") -> 0 | AO23: -1439.042 | AP23: 1439.042 | AQ23: KESİN | AR23: 0 | AS23: 860.541 | AT23: -683.012 | AU23: KESİN | AV23: 1357.15 | AW23: =IF(AND(ISNUMBER(AV23),ISNUMBER(AT23)),IF(AT23<>0,AV23/ABS(AT23),""),"") -> 1.9870075 | AX23: 1 | AY23: 0 | AZ23: YTD-1 2025/06 (+1,357.2): kalem = yatırım bölüm toplamı | BA23: 1
A24: ALFAS | B24: Kira anapara | C24: 2025/03 | D24: 1 | E24: 1 | F24: =SUM(G24:M24) -> 1 | G24: 0 | H24: 0 | I24: 0 | J24: 1 | K24: 0 | L24: 0 | M24: 0 | N24: 0 | O24: 1 | P24: 1 | Q24: 0 | R24: 0 | S24: 0 | T24: 1.216 | U24: -1.493 | V24: 0 | W24: =IF(RIGHT(C24,2)="12",IF(ISNUMBER(T24),T24,""),IF(COUNT(T24,U24,V24)=3,T24+U24-V24,"")) -> -0.277 | X24: -0.277 | Y24: 0 | Z24: 0 | AA24: -1.493 | AB24: 1.216 | AC24: 1 | AD24: 0 | AE24: 0 | AF24: 1.216 | AG24: =COUNTIF(Y24:AB24,">0") -> 1 | AH24: 0 | AI24: 0 | AJ24: =IF(ISNUMBER(X24),IF(X24>0,"+",IF(X24<0,"−","0")),IF(ISNUMBER(W24),IF(W24>0,"+",IF(W24<0,"−","0")),"yok")) -> − | AK24: =IF(AND(RIGHT(C24,2)<>"12",ISNUMBER(U24),ISNUMBER(V24)),U24-V24,"") -> -1.493 | AL24: =IF(AND(ISNUMBER(AK24),ISNUMBER(V24)),IF(V24<>0,AK24/ABS(V24),""),"") | AM24: =IF(ISNUMBER(AK24),IF(AK24>1,1,0),"") -> 0 | AN24: =IF(ISNUMBER(AK24),IF(AK24>0.05*ABS(V24),1,0),"") -> 0 | AO24: -0.277 | AP24: 0.277 | AQ24: KESİN | AR24: 0 | AS24: 2390.226 | AT24: 1133.119 | AU24: KESİN | AV24: 1.216 | AW24: =IF(AND(ISNUMBER(AV24),ISNUMBER(AT24)),IF(AT24<>0,AV24/ABS(AT24),""),"") -> 0.0010731441 | AX24: 1 | AY24: 0 | AZ24: YTD 2025/03 (+1.2): pozitif değer bölüm toplamına pozitif giriyor | BA24: 0
A25: ALFAS | B25: Kira anapara | C25: 2026/03 | D25: 1 | E25: 1 | F25: =SUM(G25:M25) -> 1 | G25: 0 | H25: 0 | I25: 0 | J25: 1 | K25: 0 | L25: 0 | M25: 0 | N25: 0 | O25: 1 | P25: 1 | Q25: 0 | R25: 0 | S25: 0 | T25: -51.928 | U25: -0.587 | V25: 1.216 | W25: =IF(RIGHT(C25,2)="12",IF(ISNUMBER(T25),T25,""),IF(COUNT(T25,U25,V25)=3,T25+U25-V25,"")) -> -53.731 | X25: -53.732 | Y25: -2.389 | Z25: 0.27 | AA25: 0.315 | AB25: -51.928 | AC25: 0 | AD25: 0 | AE25: 1 | AF25: 1.216 | AG25: =COUNTIF(Y25:AB25,">0") -> 2 | AH25: 0 | AI25: 0.585 | AJ25: =IF(ISNUMBER(X25),IF(X25>0,"+",IF(X25<0,"−","0")),IF(ISNUMBER(W25),IF(W25>0,"+",IF(W25<0,"−","0")),"yok")) -> − | AK25: =IF(AND(RIGHT(C25,2)<>"12",ISNUMBER(U25),ISNUMBER(V25)),U25-V25,"") -> -1.803 | AL25: =IF(AND(ISNUMBER(AK25),ISNUMBER(V25)),IF(V25<>0,AK25/ABS(V25),""),"") -> -1.4827303 | AM25: =IF(ISNUMBER(AK25),IF(AK25>1,1,0),"") -> 0 | AN25: =IF(ISNUMBER(AK25),IF(AK25>0.05*ABS(V25),1,0),"") -> 0 | AO25: -53.734 | AP25: 53.734 | AQ25: KESİN | AR25: 0 | AS25: 1104.957 | AU25: NULL | AV25: 1.216 | AW25: =IF(AND(ISNUMBER(AV25),ISNUMBER(AT25)),IF(AT25<>0,AV25/ABS(AT25),""),"") | AX25: 1 | AY25: 0 | AZ25: YTD-1 2025/03 (+1.2): pozitif değer bölüm toplamına pozitif giriyor | BA25: 0
A26: ARASE | B26: Kira anapara | C26: 2025/09 | D26: 1 | E26: 1 | F26: =SUM(G26:M26) -> 1 | G26: 1 | H26: 0 | I26: 0 | J26: 0 | K26: 0 | L26: 0 | M26: 0 | N26: 1 | O26: 0 | P26: 1 | Q26: 1 | R26: 1 | S26: 0 | T26: -111.307 | U26: -95.34 | V26: -280.908 | W26: =IF(RIGHT(C26,2)="12",IF(ISNUMBER(T26),T26,""),IF(COUNT(T26,U26,V26)=3,T26+U26-V26,"")) -> 74.261 | X26: 74.261 | Y26: 185.568 | Z26: -33.028 | AA26: -36.916 | AB26: -41.361 | AC26: 0 | AD26: 0 | AE26: 0 | AF26: 0 | AG26: =COUNTIF(Y26:AB26,">0") -> 1 | AH26: 0 | AI26: 185.568 | AJ26: =IF(ISNUMBER(X26),IF(X26>0,"+",IF(X26<0,"−","0")),IF(ISNUMBER(W26),IF(W26>0,"+",IF(W26<0,"−","0")),"yok")) -> + | AK26: =IF(AND(RIGHT(C26,2)<>"12",ISNUMBER(U26),ISNUMBER(V26)),U26-V26,"") -> 185.568 | AL26: =IF(AND(ISNUMBER(AK26),ISNUMBER(V26)),IF(V26<>0,AK26/ABS(V26),""),"") -> 0.66060062 | AM26: =IF(ISNUMBER(AK26),IF(AK26>1,1,0),"") -> 1 | AN26: =IF(ISNUMBER(AK26),IF(AK26>0.05*ABS(V26),1,0),"") -> 1 | AO26: 74.261 | AP26: 0 | AQ26: KESİN | AR26: 1 | AS26: 6926.653 | AT26: 6903.972 | AU26: KOŞULLU | AV26: 185.568 | AW26: =IF(AND(ISNUMBER(AV26),ISNUMBER(AT26)),IF(AT26<>0,AV26/ABS(AT26),""),"") -> 0.02687844 | AX26: 0 | AY26: 1 | BA26: 0
A27: ARENA | B27: Kira anapara | C27: 2026/03 | D27: 1 | E27: 1 | F27: =SUM(G27:M27) -> 1 | G27: 0 | H27: 0 | I27: 0 | J27: 1 | K27: 0 | L27: 0 | M27: 0 | N27: 0 | O27: 1 | P27: 1 | Q27: 0 | R27: 0 | S27: 0 | T27: 23.396 | U27: -145.167 | V27: -33.641 | W27: =IF(RIGHT(C27,2)="12",IF(ISNUMBER(T27),T27,""),IF(COUNT(T27,U27,V27)=3,T27+U27-V27,"")) -> -88.13 | X27: -88.129 | Y27: -21.368 | Z27: -20.898 | AA27: -69.258 | AB27: 23.396 | AC27: 1 | AD27: 0 | AE27: 0 | AF27: 23.396 | AG27: =COUNTIF(Y27:AB27,">0") -> 1 | AH27: 0 | AI27: 0 | AJ27: =IF(ISNUMBER(X27),IF(X27>0,"+",IF(X27<0,"−","0")),IF(ISNUMBER(W27),IF(W27>0,"+",IF(W27<0,"−","0")),"yok")) -> − | AK27: =IF(AND(RIGHT(C27,2)<>"12",ISNUMBER(U27),ISNUMBER(V27)),U27-V27,"") -> -111.526 | AL27: =IF(AND(ISNUMBER(AK27),ISNUMBER(V27)),IF(V27<>0,AK27/ABS(V27),""),"") -> -3.3151809 | AM27: =IF(ISNUMBER(AK27),IF(AK27>1,1,0),"") -> 0 | AN27: =IF(ISNUMBER(AK27),IF(AK27>0.05*ABS(V27),1,0),"") -> 0 | AO27: -145.167 | AP27: 145.167 | AQ27: TÜRETİLMİŞ | AR27: 0 | AS27: 1640.346 | AT27: 1354.124 | AU27: TÜRETİLMİŞ | AV27: 23.396 | AW27: =IF(AND(ISNUMBER(AV27),ISNUMBER(AT27)),IF(AT27<>0,AV27/ABS(AT27),""),"") -> 0.017277591 | AX27: 1 | AY27: 0 | AZ27: YTD 2026/03 (+23.4): pozitif değer bölüm toplamına pozitif giriyor | BA27: 0
A28: ARENA | B28: MDV+MODV alımı | C28: 2025/03 | D28: 1 | E28: 1 | F28: =SUM(G28:M28) -> 2 | G28: 0 | H28: 0 | I28: 0 | J28: 0 | K28: 1 | L28: 0 | M28: 1 | N28: 0 | O28: 1 | P28: 1 | Q28: 0 | R28: 0 | S28: 0 | T28: -25.899 | U28: -64.478 | V28: 13.459 | W28: =IF(RIGHT(C28,2)="12",IF(ISNUMBER(T28),T28,""),IF(COUNT(T28,U28,V28)=3,T28+U28-V28,"")) -> -103.836 | X28: -103.837 | Y28: -58.298 | Z28: 51.91 | AA28: -71.549 | AB28: -25.899 | AC28: 0 | AD28: 0 | AE28: 1 | AF28: 13.459 | AG28: =COUNTIF(Y28:AB28,">0") -> 1 | AH28: 0 | AI28: 51.91 | AJ28: =IF(ISNUMBER(X28),IF(X28>0,"+",IF(X28<0,"−","0")),IF(ISNUMBER(W28),IF(W28>0,"+",IF(W28<0,"−","0")),"yok")) -> − | AK28: =IF(AND(RIGHT(C28,2)<>"12",ISNUMBER(U28),ISNUMBER(V28)),U28-V28,"") -> -77.937 | AL28: =IF(AND(ISNUMBER(AK28),ISNUMBER(V28)),IF(V28<>0,AK28/ABS(V28),""),"") -> -5.7906977 | AM28: =IF(ISNUMBER(AK28),IF(AK28>1,1,0),"") -> 0 | AN28: =IF(ISNUMBER(AK28),IF(AK28>0.05*ABS(V28),1,0),"") -> 0 | AO28: -64.479 | AP28: 64.479 | AQ28: TÜRETİLMİŞ | AR28: 0 | AS28: -2247.278 | AT28: -2416.314 | AU28: TÜRETİLMİŞ | AV28: 13.459 | AW28: =IF(AND(ISNUMBER(AV28),ISNUMBER(AT28)),IF(AT28<>0,AV28/ABS(AT28),""),"") -> 0.0055700542 | AX28: 1 | AY28: 0 | AZ28: YTD-1 2024/03 (+13.5): pozitif değer bölüm toplamına pozitif giriyor | BA28: 0
A29: ARENA | B29: MDV+MODV alımı | C29: 2025/06 | D29: 1 | E29: 1 | F29: =SUM(G29:M29) -> 1 | G29: 0 | H29: 0 | I29: 0 | J29: 0 | K29: 0 | L29: 0 | M29: 1 | N29: 0 | O29: 0 | P29: 1 | Q29: 0 | R29: 0 | S29: 0 | T29: -45.326 | U29: -64.478 | V29: -44.839 | W29: =IF(RIGHT(C29,2)="12",IF(ISNUMBER(T29),T29,""),IF(COUNT(T29,U29,V29)=3,T29+U29-V29,"")) -> -64.965 | X29: -64.965 | Y29: 51.91 | Z29: -71.549 | AA29: -25.899 | AB29: -19.426 | AC29: 0 | AD29: 0 | AE29: 0 | AF29: 0 | AG29: =COUNTIF(Y29:AB29,">0") -> 1 | AH29: 0 | AI29: 51.91 | AJ29: =IF(ISNUMBER(X29),IF(X29>0,"+",IF(X29<0,"−","0")),IF(ISNUMBER(W29),IF(W29>0,"+",IF(W29<0,"−","0")),"yok")) -> − | AK29: =IF(AND(RIGHT(C29,2)<>"12",ISNUMBER(U29),ISNUMBER(V29)),U29-V29,"") -> -19.639 | AL29: =IF(AND(ISNUMBER(AK29),ISNUMBER(V29)),IF(V29<>0,AK29/ABS(V29),""),"") -> -0.43798925 | AM29: =IF(ISNUMBER(AK29),IF(AK29>1,1,0),"") -> 0 | AN29: =IF(ISNUMBER(AK29),IF(AK29>0.05*ABS(V29),1,0),"") -> 0 | AO29: -103.837 | AP29: 103.837 | AQ29: TÜRETİLMİŞ | AR29: 0 | AS29: -2422.205 | AT29: -2651.842 | AU29: TÜRETİLMİŞ | AV29: 51.91 | AW29: =IF(AND(ISNUMBER(AV29),ISNUMBER(AT29)),IF(AT29<>0,AV29/ABS(AT29),""),"") -> 0.019575073 | AX29: 0 | AY29: 0 | BA29: 0
A30: ARENA | B30: MDV+MODV alımı | C30: 2025/09 | D30: 1 | E30: 1 | F30: =SUM(G30:M30) -> 1 | G30: 0 | H30: 0 | I30: 0 | J30: 0 | K30: 1 | L30: 0 | M30: 0 | N30: 0 | O30: 1 | P30: 0 | Q30: 0 | R30: 0 | S30: 0 | T30: -95.94 | U30: -64.478 | V30: 7.07 | W30: =IF(RIGHT(C30,2)="12",IF(ISNUMBER(T30),T30,""),IF(COUNT(T30,U30,V30)=3,T30+U30-V30,"")) -> -167.488 | X30: -167.49 | Y30: -71.549 | Z30: -25.899 | AA30: -19.426 | AB30: -50.614 | AC30: 0 | AD30: 0 | AE30: 1 | AF30: 7.07 | AG30: =COUNTIF(Y30:AB30,">0") -> 0 | AH30: 0 | AI30: 0 | AJ30: =IF(ISNUMBER(X30),IF(X30>0,"+",IF(X30<0,"−","0")),IF(ISNUMBER(W30),IF(W30>0,"+",IF(W30<0,"−","0")),"yok")) -> − | AK30: =IF(AND(RIGHT(C30,2)<>"12",ISNUMBER(U30),ISNUMBER(V30)),U30-V30,"") -> -71.548 | AL30: =IF(AND(ISNUMBER(AK30),ISNUMBER(V30)),IF(V30<>0,AK30/ABS(V30),""),"") -> -10.119943 | AM30: =IF(ISNUMBER(AK30),IF(AK30>1,1,0),"") -> 0 | AN30: =IF(ISNUMBER(AK30),IF(AK30>0.05*ABS(V30),1,0),"") -> 0 | AO30: -64.965 | AP30: 64.965 | AQ30: TÜRETİLMİŞ | AR30: 0 | AS30: -1846.846 | AT30: -2044.686 | AU30: TÜRETİLMİŞ | AV30: 7.07 | AW30: =IF(AND(ISNUMBER(AV30),ISNUMBER(AT30)),IF(AT30<>0,AV30/ABS(AT30),""),"") -> 0.0034577436 | AX30: 1 | AY30: 0 | AZ30: YTD-1 2024/09 (+7.1): pozitif değer bölüm toplamına pozitif giriyor | BA30: 0
A31: ARFYE | B31: MDV+MODV alımı | C31: 2025/09 | D31: 1 | E31: 1 | F31: =SUM(G31:M31) -> 1 | G31: 0 | H31: 0 | I31: 0 | J31: 0 | K31: 1 | L31: 0 | M31: 0 | N31: 0 | O31: 1 | P31: 0 | Q31: 0 | R31: 0 | S31: 0 | T31: -5.316 | U31: -8.67 | V31: 5.366 | W31: =IF(RIGHT(C31,2)="12",IF(ISNUMBER(T31),T31,""),IF(COUNT(T31,U31,V31)=3,T31+U31-V31,"")) -> -19.352 | X31: -19.353 | Y31: -14.037 | Z31: -2.11 | AA31: -0.591 | AC31: 0 | AD31: 0 | AE31: 1 | AF31: 5.366 | AG31: =COUNTIF(Y31:AB31,">0") -> 0 | AH31: 0 | AI31: 0 | AJ31: =IF(ISNUMBER(X31),IF(X31>0,"+",IF(X31<0,"−","0")),IF(ISNUMBER(W31),IF(W31>0,"+",IF(W31<0,"−","0")),"yok")) -> − | AK31: =IF(AND(RIGHT(C31,2)<>"12",ISNUMBER(U31),ISNUMBER(V31)),U31-V31,"") -> -14.036 | AL31: =IF(AND(ISNUMBER(AK31),ISNUMBER(V31)),IF(V31<>0,AK31/ABS(V31),""),"") -> -2.6157287 | AM31: =IF(ISNUMBER(AK31),IF(AK31>1,1,0),"") -> 0 | AN31: =IF(ISNUMBER(AK31),IF(AK31>0.05*ABS(V31),1,0),"") -> 0 | AQ31: NULL | AR31: 0 | AU31: NULL | AV31: 5.366 | AW31: =IF(AND(ISNUMBER(AV31),ISNUMBER(AT31)),IF(AT31<>0,AV31/ABS(AT31),""),"") | AX31: 1 | AY31: 0 | AZ31: YTD-1 2024/09 (+5.4): yatırım alt toplamı tutmuyor; kalem = yatırım bölüm toplamı | BA31: 0
A32: ARSAN | B32: MDV+MODV alımı | C32: 2025/03 | D32: 1 | E32: 1 | F32: =SUM(G32:M32) -> 2 | G32: 0 | H32: 0 | I32: 0 | J32: 0 | K32: 0 | L32: 1 | M32: 1 | N32: 1 | O32: 0 | P32: 1 | Q32: 0 | R32: 0 | S32: 0 | T32: -53.814 | U32: -31.764 | V32: -140.411 | W32: =IF(RIGHT(C32,2)="12",IF(ISNUMBER(T32),T32,""),IF(COUNT(T32,U32,V32)=3,T32+U32-V32,"")) -> 54.833 | X32: 54.832 | Y32: 87.261 | Z32: -8.852 | AA32: 30.237 | AB32: -53.814 | AC32: 0 | AD32: 0 | AE32: 0 | AF32: 0 | AG32: =COUNTIF(Y32:AB32,">0") -> 2 | AH32: 0 | AI32: 117.498 | AJ32: =IF(ISNUMBER(X32),IF(X32>0,"+",IF(X32<0,"−","0")),IF(ISNUMBER(W32),IF(W32>0,"+",IF(W32<0,"−","0")),"yok")) -> + | AK32: =IF(AND(RIGHT(C32,2)<>"12",ISNUMBER(U32),ISNUMBER(V32)),U32-V32,"") -> 108.647 | AL32: =IF(AND(ISNUMBER(AK32),ISNUMBER(V32)),IF(V32<>0,AK32/ABS(V32),""),"") -> 0.77377841 | AM32: =IF(ISNUMBER(AK32),IF(AK32>1,1,0),"") -> 1 | AN32: =IF(ISNUMBER(AK32),IF(AK32>0.05*ABS(V32),1,0),"") -> 1 | AO32: 54.832 | AP32: 54.832 | AQ32: KESİN | AR32: 0 | AS32: 891.031 | AU32: NULL | AV32: 108.647 | AW32: =IF(AND(ISNUMBER(AV32),ISNUMBER(AT32)),IF(AT32<>0,AV32/ABS(AT32),""),"") | AX32: 0 | AY32: 1 | BA32: 0
A33: ARSAN | B33: MDV+MODV alımı | C33: 2025/06 | D33: 1 | E33: 1 | F33: =SUM(G33:M33) -> 2 | G33: 0 | H33: 0 | I33: 0 | J33: 0 | K33: 0 | L33: 1 | M33: 1 | N33: 0 | O33: 0 | P33: 1 | Q33: 0 | R33: 0 | S33: 0 | T33: -85.366 | U33: -31.764 | V33: -53.149 | W33: =IF(RIGHT(C33,2)="12",IF(ISNUMBER(T33),T33,""),IF(COUNT(T33,U33,V33)=3,T33+U33-V33,"")) -> -63.981 | X33: -63.981 | Y33: -8.852 | Z33: 30.237 | AA33: -53.814 | AB33: -31.552 | AC33: 0 | AD33: 0 | AE33: 0 | AF33: 0 | AG33: =COUNTIF(Y33:AB33,">0") -> 1 | AH33: 0 | AI33: 30.237 | AJ33: =IF(ISNUMBER(X33),IF(X33>0,"+",IF(X33<0,"−","0")),IF(ISNUMBER(W33),IF(W33>0,"+",IF(W33<0,"−","0")),"yok")) -> − | AK33: =IF(AND(RIGHT(C33,2)<>"12",ISNUMBER(U33),ISNUMBER(V33)),U33-V33,"") -> 21.385 | AL33: =IF(AND(ISNUMBER(AK33),ISNUMBER(V33)),IF(V33<>0,AK33/ABS(V33),""),"") -> 0.4023594 | AM33: =IF(ISNUMBER(AK33),IF(AK33>1,1,0),"") -> 1 | AN33: =IF(ISNUMBER(AK33),IF(AK33>0.05*ABS(V33),1,0),"") -> 1 | AO33: -63.981 | AP33: 63.981 | AQ33: KESİN | AR33: 0 | AS33: 1159.211 | AT33: 1086.873 | AU33: KOŞULLU | AV33: 21.385 | AW33: =IF(AND(ISNUMBER(AV33),ISNUMBER(AT33)),IF(AT33<>0,AV33/ABS(AT33),""),"") -> 0.019675711 | AX33: 0 | AY33: 1 | BA33: 0
A34: ARSAN | B34: MDV+MODV alımı | C34: 2025/09 | D34: 1 | E34: 1 | F34: =SUM(G34:M34) -> 2 | G34: 0 | H34: 0 | I34: 0 | J34: 0 | K34: 0 | L34: 1 | M34: 1 | N34: 0 | O34: 0 | P34: 1 | Q34: 0 | R34: 0 | S34: 0 | T34: -344.462 | U34: -31.764 | V34: -62.002 | W34: =IF(RIGHT(C34,2)="12",IF(ISNUMBER(T34),T34,""),IF(COUNT(T34,U34,V34)=3,T34+U34-V34,"")) -> -314.224 | X34: -314.224 | Y34: 30.237 | Z34: -53.814 | AA34: -31.552 | AB34: -259.095 | AC34: 0 | AD34: 0 | AE34: 0 | AF34: 0 | AG34: =COUNTIF(Y34:AB34,">0") -> 1 | AH34: 0 | AI34: 30.237 | AJ34: =IF(ISNUMBER(X34),IF(X34>0,"+",IF(X34<0,"−","0")),IF(ISNUMBER(W34),IF(W34>0,"+",IF(W34<0,"−","0")),"yok")) -> − | AK34: =IF(AND(RIGHT(C34,2)<>"12",ISNUMBER(U34),ISNUMBER(V34)),U34-V34,"") -> 30.238 | AL34: =IF(AND(ISNUMBER(AK34),ISNUMBER(V34)),IF(V34<>0,AK34/ABS(V34),""),"") -> 0.48769395 | AM34: =IF(ISNUMBER(AK34),IF(AK34>1,1,0),"") -> 1 | AN34: =IF(ISNUMBER(AK34),IF(AK34>0.05*ABS(V34),1,0),"") -> 1 | AO34: -314.225 | AP34: 314.225 | AQ34: KESİN | AR34: 0 | AS34: 1523.524 | AU34: NULL | AV34: 30.238 | AW34: =IF(AND(ISNUMBER(AV34),ISNUMBER(AT34)),IF(AT34<>0,AV34/ABS(AT34),""),"") | AX34: 0 | AY34: 1 | BA34: 0
A35: ARTMS | B35: MDV+MODV alımı | C35: 2026/03 | D35: 1 | E35: 1 | F35: =SUM(G35:M35) -> 1 | G35: 0 | H35: 0 | I35: 0 | J35: 0 | K35: 0 | L35: 0 | M35: 1 | N35: 0 | O35: 0 | P35: 1 | Q35: 0 | R35: 0 | S35: 0 | T35: -16.307 | U35: -806.166 | V35: -164.921 | W35: =IF(RIGHT(C35,2)="12",IF(ISNUMBER(T35),T35,""),IF(COUNT(T35,U35,V35)=3,T35+U35-V35,"")) -> -657.552 | X35: -657.552 | Y35: 118.784 | Z35: -111.246 | AA35: -648.782 | AB35: -16.307 | AC35: 0 | AD35: 0 | AE35: 0 | AF35: 0 | AG35: =COUNTIF(Y35:AB35,">0") -> 1 | AH35: 0 | AI35: 118.784 | AJ35: =IF(ISNUMBER(X35),IF(X35>0,"+",IF(X35<0,"−","0")),IF(ISNUMBER(W35),IF(W35>0,"+",IF(W35<0,"−","0")),"yok")) -> − | AK35: =IF(AND(RIGHT(C35,2)<>"12",ISNUMBER(U35),ISNUMBER(V35)),U35-V35,"") -> -641.245 | AL35: =IF(AND(ISNUMBER(AK35),ISNUMBER(V35)),IF(V35<>0,AK35/ABS(V35),""),"") -> -3.888195 | AM35: =IF(ISNUMBER(AK35),IF(AK35>1,1,0),"") -> 0 | AN35: =IF(ISNUMBER(AK35),IF(AK35>0.05*ABS(V35),1,0),"") -> 0 | AO35: -657.553 | AP35: 657.553 | AQ35: KESİN | AR35: 0 | AS35: 494.632 | AU35: NULL | AV35: 118.784 | AW35: =IF(AND(ISNUMBER(AV35),ISNUMBER(AT35)),IF(AT35<>0,AV35/ABS(AT35),""),"") | AX35: 0 | AY35: 0 | BA35: 0
A36: ASUZU | B36: Kira anapara | C36: 2025/09 | D36: 1 | E36: 1 | F36: =SUM(G36:M36) -> 1 | G36: 0 | H36: 0 | I36: 0 | J36: 1 | K36: 0 | L36: 0 | M36: 0 | N36: 0 | O36: 1 | P36: 1 | Q36: 0 | R36: 0 | S36: 1 | T36: -89.628 | U36: -102.262 | V36: 16.624 | W36: =IF(RIGHT(C36,2)="12",IF(ISNUMBER(T36),T36,""),IF(COUNT(T36,U36,V36)=3,T36+U36-V36,"")) -> -208.514 | X36: -208.514 | Y36: -118.886 | Z36: -193.424 | AA36: 97.07 | AB36: 6.725 | AC36: 0 | AD36: 0 | AE36: 1 | AF36: 16.624 | AG36: =COUNTIF(Y36:AB36,">0") -> 2 | AH36: 103.795 | AI36: 0 | AJ36: =IF(ISNUMBER(X36),IF(X36>0,"+",IF(X36<0,"−","0")),IF(ISNUMBER(W36),IF(W36>0,"+",IF(W36<0,"−","0")),"yok")) -> − | AK36: =IF(AND(RIGHT(C36,2)<>"12",ISNUMBER(U36),ISNUMBER(V36)),U36-V36,"") -> -118.886 | AL36: =IF(AND(ISNUMBER(AK36),ISNUMBER(V36)),IF(V36<>0,AK36/ABS(V36),""),"") -> -7.1514678 | AM36: =IF(ISNUMBER(AK36),IF(AK36>1,1,0),"") -> 0 | AN36: =IF(ISNUMBER(AK36),IF(AK36>0.05*ABS(V36),1,0),"") -> 0 | AO36: -208.514 | AP36: 208.514 | AQ36: KESİN | AR36: 0 | AS36: 521.732 | AT36: -1566.203 | AU36: KOŞULLU | AV36: 16.624 | AW36: =IF(AND(ISNUMBER(AV36),ISNUMBER(AT36)),IF(AT36<>0,AV36/ABS(AT36),""),"") -> 0.010614205 | AX36: 1 | AY36: 0 | AZ36: YTD-1 2024/09 (+16.6): pozitif değer bölüm toplamına pozitif giriyor | BA36: 0
A37: ASUZU | B37: Kira anapara | C37: 2026/03 | D37: 1 | E37: 1 | F37: =SUM(G37:M37) -> 1 | G37: 0 | H37: 1 | I37: 0 | J37: 0 | K37: 0 | L37: 0 | M37: 0 | N37: 0 | O37: 0 | P37: 1 | Q37: 1 | R37: 1 | S37: 0 | T37: -41.839 | U37: -175.537 | V37: -193.424 | W37: =IF(RIGHT(C37,2)="12",IF(ISNUMBER(T37),T37,""),IF(COUNT(T37,U37,V37)=3,T37+U37-V37,"")) -> -23.952 | X37: -23.951 | Y37: 97.07 | Z37: 6.725 | AA37: -85.908 | AB37: -41.839 | AC37: 0 | AD37: 0 | AE37: 0 | AF37: 0 | AG37: =COUNTIF(Y37:AB37,">0") -> 2 | AH37: 0 | AI37: 103.795 | AJ37: =IF(ISNUMBER(X37),IF(X37>0,"+",IF(X37<0,"−","0")),IF(ISNUMBER(W37),IF(W37>0,"+",IF(W37<0,"−","0")),"yok")) -> − | AK37: =IF(AND(RIGHT(C37,2)<>"12",ISNUMBER(U37),ISNUMBER(V37)),U37-V37,"") -> 17.887 | AL37: =IF(AND(ISNUMBER(AK37),ISNUMBER(V37)),IF(V37<>0,AK37/ABS(V37),""),"") -> 0.092475598 | AM37: =IF(ISNUMBER(AK37),IF(AK37>1,1,0),"") -> 1 | AN37: =IF(ISNUMBER(AK37),IF(AK37>0.05*ABS(V37),1,0),"") -> 1 | AO37: -23.951 | AP37: 23.951 | AQ37: KESİN | AR37: 0 | AS37: 1480.526 | AT37: -210.719 | AU37: KESİN | AV37: 17.887 | AW37: =IF(AND(ISNUMBER(AV37),ISNUMBER(AT37)),IF(AT37<>0,AV37/ABS(AT37),""),"") -> 0.084885558 | AX37: 0 | AY37: 1 | BA37: 0
